Workbook

Sheet Game Info
B2: Total Bet | C2: 5
B3: Lines | C3: 5
B5: GAME RULES | I5: BASE GAME REELS | Q5: PAYTABLE
B6: WILD matches any other symbol on the payline. Wins with exactly one WILD pay 2x the regular win amount. Wins with exactly two WILD pay 4x the regular win amount. The progressive jackpot is won by getting 3x WILD on line 1. | I6: Pos. | J6: Reel 1 | K6: Weight 1 | L6: Reel 2 | M6: Weight 2 | N6: Reel 3 | O6: Weight 3 | Q6: Symbol | R6: 1x | S6: 2x | T6: 3x
I7: 1 | J7: WILD | K7: 6 | L7: WILD | M7: 3 | N7: WILD | O7: 2 | Q7: WILD | R7: -- | S7: -- | T7: Jackpot | U7: <-- Line 1, only
I8: 2 | J8: BLANK | K8: 8 | L8: BLANK | M8: 8 | N8: BLANK | O8: 1 | Q8: WILD | R8: -- | S8: -- | T8: 1000 | U8: <-- Lines 2 through 5, only
I9: 3 | J9: BAR1 | K9: 15 | L9: BAR1 | M9: 15 | N9: BAR1 | O9: 15 | Q9: SEVEN | R9: -- | S9: -- | T9: 80
I10: 4 | J10: BLANK | K10: 15 | L10: BLANK | M10: 10 | N10: BLANK | O10: 10 | Q10: BAR3 | R10: -- | S10: -- | T10: 40
B11: PAY LINES | I11: 5 | J11: SEVEN | K11: 10 | L11: SEVEN | M11: 5 | N11: SEVEN | O11: 5 | Q11: BAR2 | R11: -- | S11: -- | T11: 25
B12: Line 1 | I12: 6 | J12: BLANK | K12: 15 | L12: BLANK | M12: 10 | N12: BLANK | O12: 10 | Q12: BAR1 | R12: -- | S12: -- | T12: 10
C13: X | D13: X | E13: X | I13: 7 | J13: BAR2 | K13: 15 | L13: BAR2 | M13: 15 | N13: BAR2 | O13: 15 | Q13: ANYBAR | R13: -- | S13: -- | T13: 5
I14: 8 | J14: BLANK | K14: 12 | L14: BLANK | M14: 12 | N14: BLANK | O14: 12 | Q14: CHERRY | R14: 2 | S14: 5 | T14: 10 | U14: <-- CHERRY pays anywhere on a line
I15: 9 | J15: BAR3 | K15: 8 | L15: BAR3 | M15: 8 | N15: BAR3 | O15: 8 | R15: BAR2 | S15: BAR2 | T15: BAR2
B16: Line 2 | C16: X | D16: X | E16: X | I16: 10 | J16: BLANK | K16: 8 | L16: BLANK | M16: 8 | N16: BLANK | O16: 8 | R16: BAR1 | S16: BAR2 | T16: BAR3
I17: 11 | J17: CHERRY | K17: 8 | L17: CHERRY | M17: 8 | N17: CHERRY | O17: 8 | Q17: Jackpot Info
I18: 12 | J18: BLANK | K18: 8 | L18: BLANK | M18: 8 | N18: BLANK | O18: 8 | Q18: Startup | R18: 10000
I19: 13 | J19: BAR1 | K19: 15 | L19: BAR1 | M19: 15 | N19: BAR1 | O19: 15 | Q19: Increment% | R19: 0.01
B20: Line 3 | I20: 14 | J20: BLANK | K20: 10 | L20: BLANK | M20: 10 | N20: BLANK | O20: 8
I21: 15 | J21: BAR3 | K21: 15 | L21: BAR3 | M21: 8 | N21: BAR3 | O21: 5
C22: X | D22: X | E22: X | I22: 16 | J22: BLANK | K22: 10 | L22: BLANK | M22: 10 | N22: BLANK | O22: 8
I23: 17 | J23: BAR2 | K23: 15 | L23: BAR2 | M23: 15 | N23: BAR2 | O23: 15
B24: Line 4 | C24: X | I24: 18 | J24: BLANK | K24: 12 | L24: BLANK | M24: 12 | N24: BLANK | O24: 5
D25: X | I25: 19 | J25: SEVEN | K25: 8 | L25: BAR1 | M25: 5 | N25: SEVEN | O25: 8
E26: X | I26: 20 | J26: BLANK | K26: 8 | L26: BLANK | M26: 8 | N26: BLANK | O26: 1
I27: * Weights are offset based on the center row.
B28: Line 5 | E28: X
D29: X
C30: X

Sheet BG
B2: Line Return | E2: Line | F2: Return (excluding JP) | H2: Jackpot Info
B3: JP Return | E3: 1 | H3: Startup | I3: ='Game Info'!R18 -> 10000
B4: Total RTP | C4: =SUM(C2:C3) -> 0 | E4: 2 | H4: Increment % | I4: ='Game Info'!R19 -> 0.01
E5: 3 | H5: Odds
E6: 4 | H6: Avg Value
E7: 5 | H7: Return
B10: Symbol Distribution - Row 0 | G10: Symbol Distribution - Row 1 | L10: Symbol Distribution - Row 2
B11: Symbol | C11: Reel 1 | D11: Reel 2 | E11: Reel 3 | G11: Symbol | H11: Reel 4 | I11: Reel 5 | J11: Reel 6 | M11: Reel 7 | N11: Reel 8 | O11: Reel 9
B12: WILD | C12: ='Symbol Distribution'!C4 -> 0 | D12: =OFFSET('Symbol Distribution'!D4,,D$10*5) -> 0 | E12: =OFFSET('Symbol Distribution'!E4,,E$10*5) -> 0 | G12: WILD | H12: ='Symbol Distribution'!H4 -> 0 | I12: =OFFSET('Symbol Distribution'!I4,,I$10*5) -> 0 | J12: =OFFSET('Symbol Distribution'!J4,,J$10*5) -> 0 | L12: WILD | M12: ='Symbol Distribution'!M4 -> 0 | N12: =OFFSET('Symbol Distribution'!N4,,N$10*5) -> 0 | O12: =OFFSET('Symbol Distribution'!O4,,O$10*5) -> 0
B13: SEVEN | C13: =OFFSET('Symbol Distribution'!C5,,C$10*5) -> 0 | D13: =OFFSET('Symbol Distribution'!D5,,D$10*5) -> 0 | E13: =OFFSET('Symbol Distribution'!E5,,E$10*5) -> 0 | G13: SEVEN | H13: =OFFSET('Symbol Distribution'!H5,,H$10*5) -> 0 | I13: =OFFSET('Symbol Distribution'!I5,,I$10*5) -> 0 | J13: =OFFSET('Symbol Distribution'!J5,,J$10*5) -> 0 | L13: SEVEN | M13: =OFFSET('Symbol Distribution'!M5,,M$10*5) -> 0 | N13: =OFFSET('Symbol Distribution'!N5,,N$10*5) -> 0 | O13: =OFFSET('Symbol Distribution'!O5,,O$10*5) -> 0
B14: BAR3 | C14: =OFFSET('Symbol Distribution'!C6,,C$10*5) -> 0 | D14: =OFFSET('Symbol Distribution'!D6,,D$10*5) -> 0 | E14: =OFFSET('Symbol Distribution'!E6,,E$10*5) -> 0 | G14: BAR3 | H14: =OFFSET('Symbol Distribution'!H6,,H$10*5) -> 0 | I14: =OFFSET('Symbol Distribution'!I6,,I$10*5) -> 0 | J14: =OFFSET('Symbol Distribution'!J6,,J$10*5) -> 0 | L14: BAR3 | M14: =OFFSET('Symbol Distribution'!M6,,M$10*5) -> 0 | N14: =OFFSET('Symbol Distribution'!N6,,N$10*5) -> 0 | O14: =OFFSET('Symbol Distribution'!O6,,O$10*5) -> 0
B15: BAR2 | C15: =OFFSET('Symbol Distribution'!C7,,C$10*5) -> 0 | D15: =OFFSET('Symbol Distribution'!D7,,D$10*5) -> 0 | E15: =OFFSET('Symbol Distribution'!E7,,E$10*5) -> 0 | G15: BAR2 | H15: =OFFSET('Symbol Distribution'!H7,,H$10*5) -> 0 | I15: =OFFSET('Symbol Distribution'!I7,,I$10*5) -> 0 | J15: =OFFSET('Symbol Distribution'!J7,,J$10*5) -> 0 | L15: BAR2 | M15: =OFFSET('Symbol Distribution'!M7,,M$10*5) -> 0 | N15: =OFFSET('Symbol Distribution'!N7,,N$10*5) -> 0 | O15: =OFFSET('Symbol Distribution'!O7,,O$10*5) -> 0
B16: BAR1 | C16: =OFFSET('Symbol Distribution'!C8,,C$10*5) -> 0 | D16: =OFFSET('Symbol Distribution'!D8,,D$10*5) -> 0 | E16: =OFFSET('Symbol Distribution'!E8,,E$10*5) -> 0 | G16: BAR1 | H16: =OFFSET('Symbol Distribution'!H8,,H$10*5) -> 0 | I16: =OFFSET('Symbol Distribution'!I8,,I$10*5) -> 0 | J16: =OFFSET('Symbol Distribution'!J8,,J$10*5) -> 0 | L16: BAR1 | M16: =OFFSET('Symbol Distribution'!M8,,M$10*5) -> 0 | N16: =OFFSET('Symbol Distribution'!N8,,N$10*5) -> 0 | O16: =OFFSET('Symbol Distribution'!O8,,O$10*5) -> 0
B17: CHERRY | C17: =OFFSET('Symbol Distribution'!C9,,C$10*5) -> 0 | D17: =OFFSET('Symbol Distribution'!D9,,D$10*5) -> 0 | E17: =OFFSET('Symbol Distribution'!E9,,E$10*5) -> 0 | G17: CHERRY | H17: =OFFSET('Symbol Distribution'!H9,,H$10*5) -> 0 | I17: =OFFSET('Symbol Distribution'!I9,,I$10*5) -> 0 | J17: =OFFSET('Symbol Distribution'!J9,,J$10*5) -> 0 | L17: CHERRY | M17: =OFFSET('Symbol Distribution'!M9,,M$10*5) -> 0 | N17: =OFFSET('Symbol Distribution'!N9,,N$10*5) -> 0 | O17: =OFFSET('Symbol Distribution'!O9,,O$10*5) -> 0
B18: BLANK | C18: =OFFSET('Symbol Distribution'!C10,,C$10*5) -> 0 | D18: =OFFSET('Symbol Distribution'!D10,,D$10*5) -> 0 | E18: =OFFSET('Symbol Distribution'!E10,,E$10*5) -> 0 | G18: BLANK | H18: =OFFSET('Symbol Distribution'!H10,,H$10*5) -> 0 | I18: =OFFSET('Symbol Distribution'!I10,,I$10*5) -> 0 | J18: =OFFSET('Symbol Distribution'!J10,,J$10*5) -> 0 | L18: BLANK | M18: =OFFSET('Symbol Distribution'!M10,,M$10*5) -> 0 | N18: =OFFSET('Symbol Distribution'!N10,,N$10*5) -> 0 | O18: =OFFSET('Symbol Distribution'!O10,,O$10*5) -> 0
B19: Total | C19: =SUM(C12:C18) -> 0 | D19: =SUM(D12:D18) -> 0 | E19: =SUM(E12:E18) -> 0 | G19: Total | H19: =SUM(H12:H18) -> 0 | I19: =SUM(I12:I18) -> 0 | J19: =SUM(J12:J18) -> 0 | L19: Total | M19: =SUM(M12:M18) -> 0 | N19: =SUM(N12:N18) -> 0 | O19: =SUM(O12:O18) -> 0
D20: Cycle | E20: =PRODUCT(C19:E19) -> 0 | I20: Cycle | J20: =PRODUCT(H19:J19) -> 0 | N20: Cycle | O20: =PRODUCT(M19:O19) -> 0
B22: Combinations
B23: Reel 1 | C23: Reel 2 | D23: Reel 3 | E23: Hits | F23: Prob | G23: Pay | H23: Return
B24: WILD | C24: WILD | D24: WILD | F24: =E24/$E$20 -> #DIV/0! | H24: =F24*G24 -> #DIV/0!
B26: SEVEN | C26: =B26 -> SEVEN | D26: =B26 -> SEVEN | F26: =E26/$E$20 -> #DIV/0! | H26: =F26*G26 -> #DIV/0!
B27: =B26 -> SEVEN | C27: =B26 -> SEVEN | D27: WILD | F27: =E27/$E$20 -> #DIV/0! | H27: =F27*G27 -> #DIV/0!
B28: =B26 -> SEVEN | C28: WILD | D28: =B26 -> SEVEN | F28: =E28/$E$20 -> #DIV/0! | H28: =F28*G28 -> #DIV/0!
B29: WILD | C29: =B26 -> SEVEN | D29: =B26 -> SEVEN | F29: =E29/$E$20 -> #DIV/0! | H29: =F29*G29 -> #DIV/0!
B30: =B26 -> SEVEN | C30: WILD | D30: WILD | F30: =E30/$E$20 -> #DIV/0! | H30: =F30*G30 -> #DIV/0!
B31: WILD | C31: =B26 -> SEVEN | D31: WILD | F31: =E31/$E$20 -> #DIV/0! | H31: =F31*G31 -> #DIV/0!
B32: WILD | C32: WILD | D32: =B26 -> SEVEN | F32: =E32/$E$20 -> #DIV/0! | H32: =F32*G32 -> #DIV/0!
B34: BAR3 | C34: =B34 -> BAR3 | D34: BAR3 | F34: =E34/$E$20 -> #DIV/0! | H34: =F34*G34 -> #DIV/0!
B35: =B34 -> BAR3 | C35: =B34 -> BAR3 | D35: WILD | F35: =E35/$E$20 -> #DIV/0! | H35: =F35*G35 -> #DIV/0!
B36: =B34 -> BAR3 | C36: WILD | D36: BAR2 | F36: =E36/$E$20 -> #DIV/0! | H36: =F36*G36 -> #DIV/0!
B37: WILD | C37: =B34 -> BAR3 | D37: BAR1 | F37: =E37/$E$20 -> #DIV/0! | H37: =F37*G37 -> #DIV/0!
B38: =B34 -> BAR3 | C38: WILD | D38: WILD | F38: =E38/$E$20 -> #DIV/0! | H38: =F38*G38 -> #DIV/0!
B39: WILD | C39: =B34 -> BAR3 | D39: WILD | F39: =E39/$E$20 -> #DIV/0! | H39: =F39*G39 -> #DIV/0!
B40: WILD | C40: WILD | D40: =B34 -> BAR3 | F40: =E40/$E$20 -> #DIV/0! | H40: =F40*G40 -> #DIV/0!
B42: BAR2 | C42: =B42 -> BAR2 | D42: =B42 -> BAR2 | F42: =E42/$E$20 -> #DIV/0! | H42: =F42*G42 -> #DIV/0!
B43: =B42 -> BAR2 | C43: =B42 -> BAR2 | D43: WILD | F43: =E43/$E$20 -> #DIV/0! | H43: =F43*G43 -> #DIV/0!
B44: =B42 -> BAR2 | C44: WILD | D44: =B42 -> BAR2 | F44: =E44/$E$20 -> #DIV/0! | H44: =F44*G44 -> #DIV/0!
B45: WILD | C45: =B42 -> BAR2 | D45: =B42 -> BAR2 | F45: =E45/$E$20 -> #DIV/0! | H45: =F45*G45 -> #DIV/0!
B46: =B42 -> BAR2 | C46: WILD | D46: WILD | F46: =E46/$E$20 -> #DIV/0! | H46: =F46*G46 -> #DIV/0!
B47: WILD | C47: =B42 -> BAR2 | D47: WILD | F47: =E47/$E$20 -> #DIV/0! | H47: =F47*G47 -> #DIV/0!
...

Sheet Symbol Distribution
B2: Symbol Distribution - Row 0 | G2: Symbol Distribution - Row 1 | L2: Symbol Distribution - Row 2
B3: Symbol | C3: Reel 1 | D3: Reel 2 | E3: Reel 3 | G3: Symbol | H3: Reel 1 | I3: Reel 2 | J3: Reel 3 | L3: Symbol | M3: Reel 1 | N3: Reel 2 | O3: Reel 3
B4: WILD | G4: WILD | L4: WILD
B5: SEVEN | G5: SEVEN | L5: SEVEN
B6: BAR3 | G6: BAR3 | L6: BAR3
B7: BAR2 | G7: BAR2 | L7: BAR2
B8: BAR1 | G8: BAR1 | L8: BAR1
B9: CHERRY | G9: CHERRY | L9: CHERRY
B10: BLANK | G10: BLANK | L10: BLANK
B11: Total | G11: Total | L11: Total
B13: BASE GAME REELS
B14: Pos. | C14: Reel 1 | D14: Weight 1 | E14: Reel 2 | F14: Weight 2 | G14: Reel 3 | H14: Weight 3
B15: -- | C15: =C35 -> BLANK | D15: =D35 -> 8 | E15: =E35 -> BLANK | F15: =F35 -> 8 | G15: =G35 -> BLANK | H15: =H35 -> 1
B16: 1 | C16: ='Game Info'!J7 -> WILD | D16: ='Game Info'!K7 -> 6 | E16: ='Game Info'!L7 -> WILD | F16: ='Game Info'!M7 -> 3 | G16: ='Game Info'!N7 -> WILD | H16: ='Game Info'!O7 -> 2
B17: 2 | C17: ='Game Info'!J8 -> BLANK | D17: ='Game Info'!K8 -> 8 | E17: ='Game Info'!L8 -> BLANK | F17: ='Game Info'!M8 -> 8 | G17: ='Game Info'!N8 -> BLANK | H17: ='Game Info'!O8 -> 1
B18: 3 | C18: ='Game Info'!J9 -> BAR1 | D18: ='Game Info'!K9 -> 15 | E18: ='Game Info'!L9 -> BAR1 | F18: ='Game Info'!M9 -> 15 | G18: ='Game Info'!N9 -> BAR1 | H18: ='Game Info'!O9 -> 15
B19: 4 | C19: ='Game Info'!J10 -> BLANK | D19: ='Game Info'!K10 -> 15 | E19: ='Game Info'!L10 -> BLANK | F19: ='Game Info'!M10 -> 10 | G19: ='Game Info'!N10 -> BLANK | H19: ='Game Info'!O10 -> 10
B20: 5 | C20: ='Game Info'!J11 -> SEVEN | D20: ='Game Info'!K11 -> 10 | E20: ='Game Info'!L11 -> SEVEN | F20: ='Game Info'!M11 -> 5 | G20: ='Game Info'!N11 -> SEVEN | H20: ='Game Info'!O11 -> 5
B21: 6 | C21: ='Game Info'!J12 -> BLANK | D21: ='Game Info'!K12 -> 15 | E21: ='Game Info'!L12 -> BLANK | F21: ='Game Info'!M12 -> 10 | G21: ='Game Info'!N12 -> BLANK | H21: ='Game Info'!O12 -> 10
B22: 7 | C22: ='Game Info'!J13 -> BAR2 | D22: ='Game Info'!K13 -> 15 | E22: ='Game Info'!L13 -> BAR2 | F22: ='Game Info'!M13 -> 15 | G22: ='Game Info'!N13 -> BAR2 | H22: ='Game Info'!O13 -> 15
B23: 8 | C23: ='Game Info'!J14 -> BLANK | D23: ='Game Info'!K14 -> 12 | E23: ='Game Info'!L14 -> BLANK | F23: ='Game Info'!M14 -> 12 | G23: ='Game Info'!N14 -> BLANK | H23: ='Game Info'!O14 -> 12
B24: 9 | C24: ='Game Info'!J15 -> BAR3 | D24: ='Game Info'!K15 -> 8 | E24: ='Game Info'!L15 -> BAR3 | F24: ='Game Info'!M15 -> 8 | G24: ='Game Info'!N15 -> BAR3 | H24: ='Game Info'!O15 -> 8
B25: 10 | C25: ='Game Info'!J16 -> BLANK | D25: ='Game Info'!K16 -> 8 | E25: ='Game Info'!L16 -> BLANK | F25: ='Game Info'!M16 -> 8 | G25: ='Game Info'!N16 -> BLANK | H25: ='Game Info'!O16 -> 8
B26: 11 | C26: ='Game Info'!J17 -> CHERRY | D26: ='Game Info'!K17 -> 8 | E26: ='Game Info'!L17 -> CHERRY | F26: ='Game Info'!M17 -> 8 | G26: ='Game Info'!N17 -> CHERRY | H26: ='Game Info'!O17 -> 8
B27: 12 | C27: ='Game Info'!J18 -> BLANK | D27: ='Game Info'!K18 -> 8 | E27: ='Game Info'!L18 -> BLANK | F27: ='Game Info'!M18 -> 8 | G27: ='Game Info'!N18 -> BLANK | H27: ='Game Info'!O18 -> 8
... B35: 20 | C35: ='Game Info'!J26 -> BLANK | D35: ='Game Info'!K26 -> 8 | E35: ='Game Info'!L26 -> BLANK | F35: ='Game Info'!M26 -> 8 | G35: ='Game Info'!N26 -> BLANK | H35: ='Game Info'!O26 -> 1
B36: -- | C36: =C16 -> WILD | D36: =D16 -> 6 | E36: =E16 -> WILD | F36: =F16 -> 3 | G36: =G16 -> WILD | H36: =H16 -> 2
B37: * Weights are offset based on the center row.
