Workbook

Sheet Game Info
B2: Bet | C2: 40
B4: GAME RULES | I4: BG Reels | P4: FG Reels | W4: Game Pays - Standard | AC4: FG Spins
B5: Base Game All wins pay in any position from left to right on adjacent reels, beginning with the leftmost reel. There are 1024 ways to win. A Wild in a winning combination is wild and substitutes for all symbols. Free Games Feature 3, 4, or 5 scattered FG symbols awards 8, 15, or 20 free games, respectively. 2, 3, 4, or 5 scattered FG symbols awards 5, 8, 15, or 20 free games, respectively. | I5: Pos. | J5: Reel 1 | K5: Reel 2 | L5: Reel 3 | M5: Reel 4 | N5: Reel 5 | P5: Pos. | Q5: Reel 1 | R5: Reel 2 | S5: Reel 3 | T5: Reel 4 | U5: Reel 5 | W5: Symbol | X5: 2x | Y5: 3x | Z5: 4x | AA5: 5x | AC5: Trigger | AD5: BG | AE5: FG
I6: 1 | J6: 10 | K6: SYM4 | L6: SYM1 | M6: 10 | N6: 10 | P6: 1 | Q6: 10 | R6: SYM4 | S6: SYM1 | T6: 10 | U6: 10 | W6: SYM1 | X6: 10 | Y6: 50 | Z6: 100 | AA6: 300 | AC6: FG x5 | AD6: 20 | AE6: 20
I7: 2 | J7: SYM3 | K7: 9 | L7: K | M7: SYM3 | N7: SYM5 | P7: 2 | Q7: SYM3 | R7: 9 | S7: K | T7: SYM3 | U7: SYM5 | W7: SYM2 | X7: 0 | Y7: 50 | Z7: 100 | AA7: 150 | AC7: FG x4 | AD7: 15 | AE7: 15
I8: 3 | J8: 9 | K8: SYM2 | L8: 10 | M8: J | N8: Q | P8: 3 | Q8: 9 | R8: SYM2 | S8: 10 | T8: J | U8: Q | W8: SYM3 | X8: 0 | Y8: 50 | Z8: 100 | AA8: 150 | AC8: FG x3 | AD8: 8 | AE8: 8
I9: 4 | J9: SYM2 | K9: J | L9: Q | M9: SYM2 | N9: K | P9: 4 | Q9: SYM2 | R9: J | S9: Q | T9: SYM2 | U9: K | W9: SYM4 | X9: 0 | Y9: 20 | Z9: 80 | AA9: 120 | AC9: FG x2 | AD9: -- | AE9: 5
I10: 5 | J10: Q | K10: K | L10: SYM5 | M10: SYM2 | N10: J | P10: 5 | Q10: Q | R10: K | S10: SYM5 | T10: SYM2 | U10: J | W10: SYM5 | X10: 0 | Y10: 20 | Z10: 80 | AA10: 120
I11: 6 | J11: 10 | K11: SYM1 | L11: J | M11: SYM2 | N11: SYM3 | P11: 6 | Q11: 10 | R11: SYM1 | S11: J | T11: SYM2 | U11: SYM3 | W11: A | X11: 0 | Y11: 10 | Z11: 50 | AA11: 100
I12: 7 | J12: SYM1 | K12: A | L12: WILD | M12: 9 | N12: 9 | P12: 7 | Q12: SYM1 | R12: A | S12: WILD | T12: 9 | U12: 9 | W12: K | X12: 0 | Y12: 10 | Z12: 50 | AA12: 100
I13: 8 | J13: SYM5 | K13: SYM3 | L13: Q | M13: Q | N13: SYM1 | P13: 8 | Q13: SYM5 | R13: SYM3 | S13: Q | T13: Q | U13: SYM1 | W13: Q | X13: 0 | Y13: 5 | Z13: 20 | AA13: 100
I14: 9 | J14: FG | K14: 10 | L14: SYM5 | M14: SYM5 | N14: Q | P14: 9 | Q14: FG | R14: 10 | S14: SYM5 | T14: SYM5 | U14: Q | W14: J | X14: 0 | Y14: 5 | Z14: 20 | AA14: 100
I15: 10 | J15: A | K15: SYM4 | L15: K | M15: 9 | N15: 9 | P15: 10 | Q15: A | R15: SYM4 | S15: K | T15: 9 | U15: 9 | W15: 10 | X15: 0 | Y15: 5 | Z15: 10 | AA15: 100
I16: 11 | J16: K | K16: K | L16: FG | M16: WILD | N16: SYM2 | P16: 11 | Q16: K | R16: K | S16: FG | T16: WILD | U16: SYM2 | W16: 9 | X16: 2 | Y16: 5 | Z16: 10 | AA16: 100
I17: 12 | J17: SYM4 | K17: SYM3 | L17: 10 | M17: A | N17: J | P17: 12 | Q17: SYM4 | R17: SYM3 | S17: 10 | T17: A | U17: J | W17: FG* | X17: 0 | Y17: 2 | Z17: 10 | AA17: 20
I18: 13 | J18: 9 | K18: A | L18: Q | M18: SYM2 | N18: SYM3 | P18: 13 | Q18: 9 | R18: A | S18: Q | T18: SYM2 | U18: SYM3 | W18: * Scatter pays are multiplied by total bet
B19: Rules for Ways Pays | I19: 14 | J19: J | K19: WILD | L19: SYM3 | M19: K | N19: Q | P19: 14 | Q19: J | R19: WILD | S19: SYM3 | T19: K | U19: Q
B20: Except for the FG symbol, all winning combinations are payable only when appearing on valid positions on adjacent reels All winning combinations amounts are multiplied by the number of winning symbols the appear on each reel. For each symbol, only the highest winning combinations is paid each spin. | I20: 15 | J20: A | K20: K | L20: A | M20: SYM4 | N20: SYM1 | P20: 15 | Q20: A | R20: K | S20: A | T20: SYM4 | U20: SYM1
I21: 16 | J21: SYM5 | K21: SYM1 | L21: SYM4 | M21: J | N21: K | P21: 16 | Q21: SYM5 | R21: SYM1 | S21: SYM4 | T21: J | U21: K
I22: 17 | J22: SYM5 | K22: Q | L22: SYM4 | M22: SYM1 | N22: Q | P22: 17 | Q22: SYM5 | R22: Q | S22: SYM4 | T22: SYM1 | U22: Q
I23: 18 | J23: SYM5 | K23: 10 | L23: SYM4 | M23: SYM1 | N23: SYM4 | P23: 18 | Q23: SYM5 | R23: 10 | S23: SYM4 | T23: SYM1 | U23: SYM4
I24: 19 | J24: Q | K24: K | L24: J | M24: SYM1 | N24: K | P24: 19 | Q24: Q | R24: K | S24: J | T24: SYM1 | U24: K
I25: 20 | J25: 10 | K25: SYM4 | L25: FG | M25: J | N25: SYM1 | P25: 20 | Q25: 10 | R25: SYM4 | S25: FG | T25: J | U25: SYM1
I26: 21 | J26: SYM5 | K26: Q | L26: 10 | M26: SYM2 | N26: 10 | P26: 21 | Q26: SYM5 | R26: Q | S26: 10 | T26: SYM2 | U26: 10
I27: 22 | J27: Q | K27: SYM2 | L27: SYM1 | M27: K | N27: SYM3 | P27: 22 | Q27: Q | R27: WILD | S27: SYM1 | T27: K | U27: SYM3
I28: 23 | J28: SYM2 | K28: A | L28: J | M28: SYM5 | N28: Q | P28: 23 | Q28: SYM2 | R28: A | S28: J | T28: SYM5 | U28: Q
B29: Example | I29: 24 | J29: SYM3 | K29: Q | L29: 10 | M29: 9 | N29: A | P29: 24 | Q29: SYM3 | R29: Q | S29: 10 | T29: 9 | U29: A
I30: 25 | J30: J | K30: SYM4 | L30: Q | M30: SYM4 | N30: SYM1 | P30: 25 | Q30: J | R30: SYM4 | S30: Q | T30: SYM4 | U30: SYM1
I31: 26 | J31: 10 | K31: J | L31: SYM1 | M31: SYM2 | N31: SYM1 | P31: 26 | Q31: 10 | R31: J | S31: SYM1 | T31: SYM2 | U31: SYM1
I32: 27 | J32: A | K32: SYM1 | L32: K | M32: J | N32: SYM1 | P32: 27 | Q32: A | R32: SYM1 | S32: K | T32: J | U32: SYM1
I33: 28 | J33: SYM4 | K33: K | L33: J | M33: A | N33: 10 | P33: 28 | Q33: SYM4 | R33: K | S33: J | T33: A | U33: 10
B34: 1 | C34: 2 | D34: 3 | E34: 1 | F34: -- | I34: 29 | J34: SYM4 | K34: SYM2 | L34: SYM3 | M34: SYM4 | N34: SYM3 | P34: 29 | Q34: SYM4 | R34: SYM2 | S34: SYM3 | T34: SYM4 | U34: SYM3
I35: 30 | J35: 9 | K35: J | L35: SYM5 | M35: Q | N35: Q | P35: 30 | Q35: 9 | R35: J | S35: SYM5 | T35: Q | U35: Q
B36: ^^^ 4 of a kind wins, 6 ways | I36: 31 | J36: SYM2 | K36: SYM5 | L36: Q | M36: SYM2 | N36: K | P36: 31 | Q36: SYM2 | R36: SYM5 | S36: Q | T36: SYM2 | U36: K
I37: 32 | J37: A | K37: K | L37: A | M37: 10 | N37: SYM3 | P37: 32 | Q37: A | R37: K | S37: A | T37: 10 | U37: SYM3
I38: 33 | J38: J | K38: FG | L38: SYM2 | M38: SYM3 | N38: A | P38: 33 | Q38: J | R38: SYM1 | S38: SYM2 | T38: SYM3 | U38: A
I39: 34 | J39: SYM3 | K39: J | L39: K | M39: K | N39: SYM4 | P39: 34 | Q39: SYM3 | R39: J | S39: K | T39: K | U39: SYM4
I40: 35 | J40: J | K40: SYM2 | L40: SYM3 | M40: SYM5 | N40: J | P40: 35 | Q40: J | R40: SYM2 | S40: SYM3 | T40: SYM5 | U40: J
I41: 36 | J41: SYM2 | K41: SYM2 | L41: SYM3 | M41: Q | N41: SYM1 | P41: 36 | Q41: SYM2 | R41: SYM2 | S41: SYM3 | T41: Q | U41: SYM1
I42: 37 | J42: SYM2 | K42: SYM2 | L42: SYM3 | M42: SYM2 | N42: K | P42: 37 | Q42: SYM2 | R42: SYM2 | S42: SYM3 | T42: SYM2 | U42: K
...

Sheet BG
B2: BG | F2: Bet | G2: ='Game Info'!C2 -> 40
B3: FG | F3: Free Games Odds
B4: Total Return
B6: Reel Height
B7: Symbol | C7: Reel 1 | D7: Reel 2 | E7: Reel 3 | F7: Reel 4 | G7: Reel 5
B8: WW | C8: ='BG Reels'!B3 -> 0 | D8: ='BG Reels'!C3 -> 1 | E8: ='BG Reels'!D3 -> 2 | F8: ='BG Reels'!E3 -> 2 | G8: ='BG Reels'!F3 -> 0
B9: SYM1 | C9: ='BG Reels'!B4 -> 6 | D9: ='BG Reels'!C4 -> 4 | E9: ='BG Reels'!D4 -> 10 | F9: ='BG Reels'!E4 -> 8 | G9: ='BG Reels'!F4 -> 17
B10: SYM2 | C10: ='BG Reels'!B5 -> 12 | D10: ='BG Reels'!C5 -> 13 | E10: ='BG Reels'!D5 -> 6 | F10: ='BG Reels'!E5 -> 9 | G10: ='BG Reels'!F5 -> 8
B11: SYM3 | C11: ='BG Reels'!B6 -> 14 | D11: ='BG Reels'!C6 -> 6 | E11: ='BG Reels'!D6 -> 11 | F11: ='BG Reels'!E6 -> 7 | G11: ='BG Reels'!F6 -> 15
B12: SYM4 | C12: ='BG Reels'!B7 -> 6 | D12: ='BG Reels'!C7 -> 10 | E12: ='BG Reels'!D7 -> 11 | F12: ='BG Reels'!E7 -> 10 | G12: ='BG Reels'!F7 -> 8
B13: SYM5 | C13: ='BG Reels'!B8 -> 6 | D13: ='BG Reels'!C8 -> 8 | E13: ='BG Reels'!D8 -> 10 | F13: ='BG Reels'!E8 -> 9 | G13: ='BG Reels'!F8 -> 5
B14: A | C14: ='BG Reels'!B9 -> 8 | D14: ='BG Reels'!C9 -> 8 | E14: ='BG Reels'!D9 -> 6 | F14: ='BG Reels'!E9 -> 5 | G14: ='BG Reels'!F9 -> 7
B15: K | C15: ='BG Reels'!B10 -> 7 | D15: ='BG Reels'!C10 -> 13 | E15: ='BG Reels'!D10 -> 9 | F15: ='BG Reels'!E10 -> 6 | G15: ='BG Reels'!F10 -> 15
B16: Q | C16: ='BG Reels'!B11 -> 11 | D16: ='BG Reels'!C11 -> 10 | E16: ='BG Reels'!D11 -> 16 | F16: ='BG Reels'!E11 -> 9 | G16: ='BG Reels'!F11 -> 14
B17: J | C17: ='BG Reels'!B12 -> 8 | D17: ='BG Reels'!C12 -> 13 | E17: ='BG Reels'!D12 -> 10 | F17: ='BG Reels'!E12 -> 6 | G17: ='BG Reels'!F12 -> 9
B18: 10 | C18: ='BG Reels'!B13 -> 16 | D18: ='BG Reels'!C13 -> 7 | E18: ='BG Reels'!D13 -> 12 | F18: ='BG Reels'!E13 -> 6 | G18: ='BG Reels'!F13 -> 10
B19: 9 | C19: ='BG Reels'!B14 -> 9 | D19: ='BG Reels'!C14 -> 5 | E19: ='BG Reels'!D14 -> 3 | F19: ='BG Reels'!E14 -> 8 | G19: ='BG Reels'!F14 -> 4
B20: FG | C20: ='BG Reels'!B15 -> 4 | D20: ='BG Reels'!C15 -> 4 | E20: ='BG Reels'!D15 -> 4 | F20: ='BG Reels'!E15 -> 1 | G20: ='BG Reels'!F15 -> 1
B21: Total | C21: =SUM(C8:C20) -> 107 | D21: =SUM(D8:D20) -> 102 | E21: =SUM(E8:E20) -> 110 | F21: =SUM(F8:F20) -> 86 | G21: =SUM(G8:G20) -> 113
F22: Cycle | G22: =PRODUCT(C21:G21) -> 11666847720
I23: Symbol Appearances
B24: =B9 -> SYM1 | I24: ='BG Reels'!I4 -> 0 | J24: ='BG Reels'!J4 -> 0 | K24: ='BG Reels'!K4 -> 0 | L24: ='BG Reels'!L4 -> 0 | M24: ='BG Reels'!M4 -> 0
B25: =B10 -> SYM2 | I25: ='BG Reels'!I5 -> 0 | J25: ='BG Reels'!J5 -> 0 | K25: ='BG Reels'!K5 -> 0 | L25: ='BG Reels'!L5 -> 0 | M25: ='BG Reels'!M5 -> 0
B26: =B11 -> SYM3 | I26: ='BG Reels'!I6 -> 0 | J26: ='BG Reels'!J6 -> 0 | K26: ='BG Reels'!K6 -> 0 | L26: ='BG Reels'!L6 -> 0 | M26: ='BG Reels'!M6 -> 0
B27: =B12 -> SYM4 | I27: ='BG Reels'!I7 -> 0 | J27: ='BG Reels'!J7 -> 0 | K27: ='BG Reels'!K7 -> 0 | L27: ='BG Reels'!L7 -> 0 | M27: ='BG Reels'!M7 -> 0
B28: =B13 -> SYM5 | I28: ='BG Reels'!I8 -> 0 | J28: ='BG Reels'!J8 -> 0 | K28: ='BG Reels'!K8 -> 0 | L28: ='BG Reels'!L8 -> 0 | M28: ='BG Reels'!M8 -> 0
B29: =B14 -> A | I29: ='BG Reels'!I9 -> 0 | J29: ='BG Reels'!J9 -> 0 | K29: ='BG Reels'!K9 -> 0 | L29: ='BG Reels'!L9 -> 0 | M29: ='BG Reels'!M9 -> 0
B30: =B15 -> K | I30: ='BG Reels'!I10 -> 0 | J30: ='BG Reels'!J10 -> 0 | K30: ='BG Reels'!K10 -> 0 | L30: ='BG Reels'!L10 -> 0 | M30: ='BG Reels'!M10 -> 0
B31: =B16 -> Q | I31: ='BG Reels'!I11 -> 0 | J31: ='BG Reels'!J11 -> 0 | K31: ='BG Reels'!K11 -> 0 | L31: ='BG Reels'!L11 -> 0 | M31: ='BG Reels'!M11 -> 0
B32: =B17 -> J | I32: ='BG Reels'!I12 -> 0 | J32: ='BG Reels'!J12 -> 0 | K32: ='BG Reels'!K12 -> 0 | L32: ='BG Reels'!L12 -> 0 | M32: ='BG Reels'!M12 -> 0
B33: =B18 -> 10 | I33: ='BG Reels'!I13 -> 0 | J33: ='BG Reels'!J13 -> 0 | K33: ='BG Reels'!K13 -> 0 | L33: ='BG Reels'!L13 -> 0 | M33: ='BG Reels'!M13 -> 0
B34: =B19 -> 9 | I34: ='BG Reels'!I14 -> 0 | J34: ='BG Reels'!J14 -> 0 | K34: ='BG Reels'!K14 -> 0 | L34: ='BG Reels'!L14 -> 0 | M34: ='BG Reels'!M14 -> 0
B35: =B20 -> FG
B37: Combination | C37: Hits | D37: Prob | E37: Pay | F37: Contribution | I37: Combination | J37: Reel 1 | K37: Reel 2 | L37: Reel 3 | M37: Reel 4 | N37: Reel 5 | O37: Hits | P37: Prob | Q37: Pay | R37: Contribution
B38: =B9 & " x5" -> SYM1 x5 | D38: =C38/$G$22 -> 0 | E38: ='Game Info'!AA6 -> 300 | F38: =D38*E38/$G$2 -> 0 | I38: FG x5 | J38: X | K38: X | L38: X | M38: X | N38: X | P38: =O38/$G$22 -> 0 | Q38: ='Game Info'!AA17 -> 20 | R38: =P38*Q38 -> 0
B39: =B10 & " x5" -> SYM2 x5 | D39: =C39/$G$22 -> 0 | E39: ='Game Info'!AA7 -> 150 | F39: =D39*E39/$G$2 -> 0 | I39: FG x4 | J39: X | K39: X | L39: X | M39: X | N39: -- | P39: =O39/$G$22 -> 0 | Q39: ='Game Info'!Z17 -> 10 | R39: =P39*Q39 -> 0
B40: =B11 & " x5" -> SYM3 x5 | D40: =C40/$G$22 -> 0 | E40: ='Game Info'!AA8 -> 150 | F40: =D40*E40/$G$2 -> 0 | I40: FG x4 | J40: X | K40: X | L40: X | M40: -- | N40: X | P40: =O40/$G$22 -> 0 | Q40: =Q39 -> 10 | R40: =P40*Q40 -> 0
B41: =B12 & " x5" -> SYM4 x5 | D41: =C41/$G$22 -> 0 | E41: ='Game Info'!AA9 -> 120 | F41: =D41*E41/$G$2 -> 0 | I41: FG x4 | J41: X | K41: X | L41: -- | M41: X | N41: X | P41: =O41/$G$22 -> 0 | Q41: =Q40 -> 10 | R41: =P41*Q41 -> 0
B42: =B13 & " x5" -> SYM5 x5 | D42: =C42/$G$22 -> 0 | E42: ='Game Info'!AA10 -> 120 | F42: =D42*E42/$G$2 -> 0 | I42: FG x4 | J42: X | K42: -- | L42: X | M42: X | N42: X | P42: =O42/$G$22 -> 0 | Q42: =Q41 -> 10 | R42: =P42*Q42 -> 0
B43: =B14 & " x5" -> A x5 | D43: =C43/$G$22 -> 0 | E43: ='Game Info'!AA11 -> 100 | F43: =D43*E43/$G$2 -> 0 | I43: FG x4 | J43: -- | K43: X | L43: X | M43: X | N43: X | P43: =O43/$G$22 -> 0 | Q43: =Q42 -> 10 | R43: =P43*Q43 -> 0
...

Sheet FG
B2: Pay per Spin | G2: Avg Spins | I2: BG | J2: FG | K2: BG Spins | L2: FG Spins
B3: Avg Spins | F3: BG | K3: ='Game Info'!AD6 -> 20 | L3: ='Game Info'!AE6 -> 20
B4: Avg Pay | F4: FG | K4: ='Game Info'!AD7 -> 15 | L4: ='Game Info'!AE7 -> 15
K5: ='Game Info'!AD8 -> 8 | L5: ='Game Info'!AE8 -> 8
K6: ='Game Info'!AD9 -> -- | L6: ='Game Info'!AE9 -> 5
B7: Symbol | C7: Reel 1 | D7: Reel 2 | E7: Reel 3 | F7: Reel 4 | G7: Reel 5
B8: WW | C8: ='FG Reels'!B3 -> 0 | D8: ='FG Reels'!C3 -> 3 | E8: ='FG Reels'!D3 -> 3 | F8: ='FG Reels'!E3 -> 2 | G8: ='FG Reels'!F3 -> 0
B9: SYM1 | C9: ='FG Reels'!B4 -> 8 | D9: ='FG Reels'!C4 -> 5 | E9: ='FG Reels'!D4 -> 12 | F9: ='FG Reels'!E4 -> 8 | G9: ='FG Reels'!F4 -> 17
B10: SYM2 | C10: ='FG Reels'!B5 -> 12 | D10: ='FG Reels'!C5 -> 12 | E10: ='FG Reels'!D5 -> 4 | F10: ='FG Reels'!E5 -> 9 | G10: ='FG Reels'!F5 -> 8
B11: SYM3 | C11: ='FG Reels'!B6 -> 14 | D11: ='FG Reels'!C6 -> 6 | E11: ='FG Reels'!D6 -> 11 | F11: ='FG Reels'!E6 -> 7 | G11: ='FG Reels'!F6 -> 15
B12: SYM4 | C12: ='FG Reels'!B7 -> 6 | D12: ='FG Reels'!C7 -> 10 | E12: ='FG Reels'!D7 -> 11 | F12: ='FG Reels'!E7 -> 10 | G12: ='FG Reels'!F7 -> 8
B13: SYM5 | C13: ='FG Reels'!B8 -> 6 | D13: ='FG Reels'!C8 -> 8 | E13: ='FG Reels'!D8 -> 10 | F13: ='FG Reels'!E8 -> 9 | G13: ='FG Reels'!F8 -> 5
B14: A | C14: ='FG Reels'!B9 -> 8 | D14: ='FG Reels'!C9 -> 8 | E14: ='FG Reels'!D9 -> 6 | F14: ='FG Reels'!E9 -> 5 | G14: ='FG Reels'!F9 -> 7
B15: K | C15: ='FG Reels'!B10 -> 7 | D15: ='FG Reels'!C10 -> 13 | E15: ='FG Reels'!D10 -> 9 | F15: ='FG Reels'!E10 -> 6 | G15: ='FG Reels'!F10 -> 15
B16: Q | C16: ='FG Reels'!B11 -> 11 | D16: ='FG Reels'!C11 -> 10 | E16: ='FG Reels'!D11 -> 16 | F16: ='FG Reels'!E11 -> 9 | G16: ='FG Reels'!F11 -> 14
B17: J | C17: ='FG Reels'!B12 -> 8 | D17: ='FG Reels'!C12 -> 13 | E17: ='FG Reels'!D12 -> 9 | F17: ='FG Reels'!E12 -> 6 | G17: ='FG Reels'!F12 -> 9
B18: 10 | C18: ='FG Reels'!B13 -> 15 | D18: ='FG Reels'!C13 -> 7 | E18: ='FG Reels'!D13 -> 13 | F18: ='FG Reels'!E13 -> 6 | G18: ='FG Reels'!F13 -> 10
B19: 9 | C19: ='FG Reels'!B14 -> 9 | D19: ='FG Reels'!C14 -> 4 | E19: ='FG Reels'!D14 -> 3 | F19: ='FG Reels'!E14 -> 8 | G19: ='FG Reels'!F14 -> 4
B20: FG | C20: ='FG Reels'!B15 -> 3 | D20: ='FG Reels'!C15 -> 3 | E20: ='FG Reels'!D15 -> 3 | F20: ='FG Reels'!E15 -> 1 | G20: ='FG Reels'!F15 -> 1
B21: Total | C21: =SUM(C8:C20) -> 107 | D21: =SUM(D8:D20) -> 102 | E21: =SUM(E8:E20) -> 110 | F21: =SUM(F8:F20) -> 86 | G21: =SUM(G8:G20) -> 113
F22: Cycle | G22: =PRODUCT(C21:G21) -> 11666847720
I23: Symbol Appearances
B24: =B9 -> SYM1 | I24: ='FG Reels'!I4 -> 0 | J24: ='FG Reels'!J4 -> 0 | K24: ='FG Reels'!K4 -> 0 | L24: ='FG Reels'!L4 -> 0 | M24: ='FG Reels'!M4 -> 0
B25: =B10 -> SYM2 | I25: ='FG Reels'!I5 -> 0 | J25: ='FG Reels'!J5 -> 0 | K25: ='FG Reels'!K5 -> 0 | L25: ='FG Reels'!L5 -> 0 | M25: ='FG Reels'!M5 -> 0
B26: =B11 -> SYM3 | I26: ='FG Reels'!I6 -> 0 | J26: ='FG Reels'!J6 -> 0 | K26: ='FG Reels'!K6 -> 0 | L26: ='FG Reels'!L6 -> 0 | M26: ='FG Reels'!M6 -> 0
B27: =B12 -> SYM4 | I27: ='FG Reels'!I7 -> 0 | J27: ='FG Reels'!J7 -> 0 | K27: ='FG Reels'!K7 -> 0 | L27: ='FG Reels'!L7 -> 0 | M27: ='FG Reels'!M7 -> 0
B28: =B13 -> SYM5 | I28: ='FG Reels'!I8 -> 0 | J28: ='FG Reels'!J8 -> 0 | K28: ='FG Reels'!K8 -> 0 | L28: ='FG Reels'!L8 -> 0 | M28: ='FG Reels'!M8 -> 0
B29: =B14 -> A | I29: ='FG Reels'!I9 -> 0 | J29: ='FG Reels'!J9 -> 0 | K29: ='FG Reels'!K9 -> 0 | L29: ='FG Reels'!L9 -> 0 | M29: ='FG Reels'!M9 -> 0
B30: =B15 -> K | I30: ='FG Reels'!I10 -> 0 | J30: ='FG Reels'!J10 -> 0 | K30: ='FG Reels'!K10 -> 0 | L30: ='FG Reels'!L10 -> 0 | M30: ='FG Reels'!M10 -> 0
B31: =B16 -> Q | I31: ='FG Reels'!I11 -> 0 | J31: ='FG Reels'!J11 -> 0 | K31: ='FG Reels'!K11 -> 0 | L31: ='FG Reels'!L11 -> 0 | M31: ='FG Reels'!M11 -> 0
B32: =B17 -> J | I32: ='FG Reels'!I12 -> 0 | J32: ='FG Reels'!J12 -> 0 | K32: ='FG Reels'!K12 -> 0 | L32: ='FG Reels'!L12 -> 0 | M32: ='FG Reels'!M12 -> 0
B33: =B18 -> 10 | I33: ='FG Reels'!I13 -> 0 | J33: ='FG Reels'!J13 -> 0 | K33: ='FG Reels'!K13 -> 0 | L33: ='FG Reels'!L13 -> 0 | M33: ='FG Reels'!M13 -> 0
B34: =B19 -> 9 | I34: ='FG Reels'!I14 -> 0 | J34: ='FG Reels'!J14 -> 0 | K34: ='FG Reels'!K14 -> 0 | L34: ='FG Reels'!L14 -> 0 | M34: ='FG Reels'!M14 -> 0
B35: =B20 -> FG
B37: Combination | C37: Hits | D37: Prob | E37: Pay | F37: Contribution | I37: Combination | J37: Reel 1 | K37: Reel 2 | L37: Reel 3 | M37: Reel 4 | N37: Reel 5 | O37: Hits | P37: Prob | Q37: Pay | R37: Contribution
B38: =B9 & " x5" -> SYM1 x5 | D38: =C38/$G$22 -> 0 | E38: ='Game Info'!AA6 -> 300 | F38: =D38*E38/BG!$G$2 -> 0 | I38: FG x5 | J38: X | K38: X | L38: X | M38: X | N38: X | P38: =O38/$G$22 -> 0 | Q38: ='Game Info'!AA17 -> 20 | R38: =P38*Q38 -> 0
B39: =B10 & " x5" -> SYM2 x5 | D39: =C39/$G$22 -> 0 | E39: ='Game Info'!AA7 -> 150 | F39: =D39*E39/BG!$G$2 -> 0 | I39: FG x4 | J39: X | K39: X | L39: X | M39: X | N39: -- | P39: =O39/$G$22 -> 0 | Q39: ='Game Info'!Z17 -> 10 | R39: =P39*Q39 -> 0
B40: =B11 & " x5" -> SYM3 x5 | D40: =C40/$G$22 -> 0 | E40: ='Game Info'!AA8 -> 150 | F40: =D40*E40/BG!$G$2 -> 0 | I40: FG x4 | J40: X | K40: X | L40: X | M40: -- | N40: X | P40: =O40/$G$22 -> 0 | Q40: =Q39 -> 10 | R40: =P40*Q40 -> 0
B41: =B12 & " x5" -> SYM4 x5 | D41: =C41/$G$22 -> 0 | E41: ='Game Info'!AA9 -> 120 | F41: =D41*E41/BG!$G$2 -> 0 | I41: FG x4 | J41: X | K41: X | L41: -- | M41: X | N41: X | P41: =O41/$G$22 -> 0 | Q41: =Q40 -> 10 | R41: =P41*Q41 -> 0
B42: =B13 & " x5" -> SYM5 x5 | D42: =C42/$G$22 -> 0 | E42: ='Game Info'!AA10 -> 120 | F42: =D42*E42/BG!$G$2 -> 0 | I42: FG x4 | J42: X | K42: -- | L42: X | M42: X | N42: X | P42: =O42/$G$22 -> 0 | Q42: =Q41 -> 10 | R42: =P42*Q42 -> 0
...

Sheet BG Reels
A2: Symbol | B2: Reel 1 | C2: Reel 2 | D2: Reel 3 | E2: Reel 4 | F2: Reel 5
A3: WILD | B3: =COUNTIF(B$23:B$172,$A3) -> 0 | C3: =COUNTIF(C$23:C$172,$A3) -> 1 | D3: =COUNTIF(D$23:D$172,$A3) -> 2 | E3: =COUNTIF(E$23:E$172,$A3) -> 2 | F3: =COUNTIF(F$23:F$172,$A3) -> 0 | H3: Symbol Appearances
A4: SYM1 | B4: =COUNTIF(B$23:B$172,$A4) -> 6 | C4: =COUNTIF(C$23:C$172,$A4) -> 4 | D4: =COUNTIF(D$23:D$172,$A4) -> 10 | E4: =COUNTIF(E$23:E$172,$A4) -> 8 | F4: =COUNTIF(F$23:F$172,$A4) -> 17 | H4: SYM1
A5: SYM2 | B5: =COUNTIF(B$23:B$172,$A5) -> 12 | C5: =COUNTIF(C$23:C$172,$A5) -> 13 | D5: =COUNTIF(D$23:D$172,$A5) -> 6 | E5: =COUNTIF(E$23:E$172,$A5) -> 9 | F5: =COUNTIF(F$23:F$172,$A5) -> 8 | H5: SYM2
A6: SYM3 | B6: =COUNTIF(B$23:B$172,$A6) -> 14 | C6: =COUNTIF(C$23:C$172,$A6) -> 6 | D6: =COUNTIF(D$23:D$172,$A6) -> 11 | E6: =COUNTIF(E$23:E$172,$A6) -> 7 | F6: =COUNTIF(F$23:F$172,$A6) -> 15 | H6: SYM3
A7: SYM4 | B7: =COUNTIF(B$23:B$172,$A7) -> 6 | C7: =COUNTIF(C$23:C$172,$A7) -> 10 | D7: =COUNTIF(D$23:D$172,$A7) -> 11 | E7: =COUNTIF(E$23:E$172,$A7) -> 10 | F7: =COUNTIF(F$23:F$172,$A7) -> 8 | H7: SYM4
A8: SYM5 | B8: =COUNTIF(B$23:B$172,$A8) -> 6 | C8: =COUNTIF(C$23:C$172,$A8) -> 8 | D8: =COUNTIF(D$23:D$172,$A8) -> 10 | E8: =COUNTIF(E$23:E$172,$A8) -> 9 | F8: =COUNTIF(F$23:F$172,$A8) -> 5 | H8: SYM5
A9: A | B9: =COUNTIF(B$23:B$172,$A9) -> 8 | C9: =COUNTIF(C$23:C$172,$A9) -> 8 | D9: =COUNTIF(D$23:D$172,$A9) -> 6 | E9: =COUNTIF(E$23:E$172,$A9) -> 5 | F9: =COUNTIF(F$23:F$172,$A9) -> 7 | H9: A
A10: K | B10: =COUNTIF(B$23:B$172,$A10) -> 7 | C10: =COUNTIF(C$23:C$172,$A10) -> 13 | D10: =COUNTIF(D$23:D$172,$A10) -> 9 | E10: =COUNTIF(E$23:E$172,$A10) -> 6 | F10: =COUNTIF(F$23:F$172,$A10) -> 15 | H10: K
A11: Q | B11: =COUNTIF(B$23:B$172,$A11) -> 11 | C11: =COUNTIF(C$23:C$172,$A11) -> 10 | D11: =COUNTIF(D$23:D$172,$A11) -> 16 | E11: =COUNTIF(E$23:E$172,$A11) -> 9 | F11: =COUNTIF(F$23:F$172,$A11) -> 14 | H11: Q
A12: J | B12: =COUNTIF(B$23:B$172,$A12) -> 8 | C12: =COUNTIF(C$23:C$172,$A12) -> 13 | D12: =COUNTIF(D$23:D$172,$A12) -> 10 | E12: =COUNTIF(E$23:E$172,$A12) -> 6 | F12: =COUNTIF(F$23:F$172,$A12) -> 9 | H12: J
A13: 10 | B13: =COUNTIF(B$23:B$172,$A13) -> 16 | C13: =COUNTIF(C$23:C$172,$A13) -> 7 | D13: =COUNTIF(D$23:D$172,$A13) -> 12 | E13: =COUNTIF(E$23:E$172,$A13) -> 6 | F13: =COUNTIF(F$23:F$172,$A13) -> 10 | H13: 10
A14: 9 | B14: =COUNTIF(B$23:B$172,$A14) -> 9 | C14: =COUNTIF(C$23:C$172,$A14) -> 5 | D14: =COUNTIF(D$23:D$172,$A14) -> 3 | E14: =COUNTIF(E$23:E$172,$A14) -> 8 | F14: =COUNTIF(F$23:F$172,$A14) -> 4 | H14: 9
A15: FG | B15: =COUNTIF(B$23:B$172,$A15) -> 4 | C15: =COUNTIF(C$23:C$172,$A15) -> 4 | D15: =COUNTIF(D$23:D$172,$A15) -> 4 | E15: =COUNTIF(E$23:E$172,$A15) -> 1 | F15: =COUNTIF(F$23:F$172,$A15) -> 1
A16: Total | B16: =SUM(B3:B15) -> 107 | C16: =SUM(C3:C15) -> 102 | D16: =SUM(D3:D15) -> 110 | E16: =SUM(E3:E15) -> 86 | F16: =SUM(F3:F15) -> 113
A18: BG Reels
A19: Pos. | B19: Reel 1 | C19: Reel 2 | D19: Reel 3 | E19: Reel 4 | F19: Reel 5
A20: -3 | B20: =OFFSET(B23,B16+$A20,) -> Q | C20: =OFFSET(C23,C16+$A20,) -> SYM3 | D20: =OFFSET(D23,D16+$A20,) -> 10 | E20: =OFFSET(E23,E16+$A20,) -> SYM4 | F20: =OFFSET(F23,F16+$A20,) -> Q
A21: -2 | B21: =OFFSET(B23,B16+$A21,) -> 10 | C21: =OFFSET(C23,C16+$A21,) -> A | D21: =OFFSET(D23,D16+$A21,) -> SYM4 | E21: =OFFSET(E23,E16+$A21,) -> 9 | F21: =OFFSET(F23,F16+$A21,) -> SYM4 | H21: =$A$4 -> SYM1 | N21: =$A$5 -> SYM2 | T21: =$A$6 -> SYM3 | Z21: =$A$7 -> SYM4 | AF21: =$A$8 -> SYM5 | AL21: =$A$9 -> A | AR21: =$A$10 -> K | AX21: =$A$11 -> Q | BD21: =$A$12 -> J | BJ21: =$A$13 -> 10 | BP21: =$A$14 -> 9
A22: -1 | B22: =OFFSET(B23,B16+$A22,) -> SYM2 | C22: =OFFSET(C23,C16+$A22,) -> SYM4 | D22: =OFFSET(D23,D16+$A22,) -> Q | E22: =OFFSET(E23,E16+$A22,) -> SYM1 | F22: =OFFSET(F23,F16+$A22,) -> J
A23: 1 | B23: =IF('Game Info'!J6="","",'Game Info'!J6) -> 10 | C23: =IF('Game Info'!K6="","",'Game Info'!K6) -> SYM4 | D23: =IF('Game Info'!L6="","",'Game Info'!L6) -> SYM1 | E23: =IF('Game Info'!M6="","",'Game Info'!M6) -> 10 | F23: =IF('Game Info'!N6="","",'Game Info'!N6) -> 10 | H23: =IF($B23="","",COUNTIF($B20:$B23,H$21)+COUNTIF($B20:$B23,$A$3)) -> 0 | I23: =IF($C23="","",COUNTIF($C20:$C23,H$21)+COUNTIF($C20:$C23,$A$3)) -> 0 | J23: =IF($D23="","",COUNTIF($D20:$D23,H$21)+COUNTIF($D20:$D23,$A$3)) -> 1 | K23: =IF($E23="","",COUNTIF($E20:$E23,H$21)+COUNTIF($E20:$E23,$A$3)) -> 1 | L23: =IF($F23="","",COUNTIF($F20:$F23,H$21)+COUNTIF($F20:$F23,$A$3)) -> 0 | N23: =IF($B23="","",COUNTIF($B20:$B23,N$21)+COUNTIF($B20:$B23,$A$3)) -> 1 | O23: =IF($C23="","",COUNTIF($C20:$C23,N$21)+COUNTIF($C20:$C23,$A$3)) -> 0 | P23: =IF($D23="","",COUNTIF($D20:$D23,N$21)+COUNTIF($D20:$D23,$A$3)) -> 0 | Q23: =IF($E23="","",COUNTIF($E20:$E23,N$21)+COUNTIF($E20:$E23,$A$3)) -> 0 | R23: =IF($F23="","",COUNTIF($F20:$F23,N$21)+COUNTIF($F20:$F23,$A$3)) -> 0 | T23: =IF($B23="","",COUNTIF($B20:$B23,T$21)+COUNTIF($B20:$B23,$A$3)) -> 0 | U23: =IF($C23="","",COUNTIF($C20:$C23,T$21)+COUNTIF($C20:$C23,$A$3)) -> 1 | V23: =IF($D23="","",COUNTIF($D20:$D23,T$21)+COUNTIF($D20:$D23,$A$3)) -> 0 | W23: =IF($E23="","",COUNTIF($E20:$E23,T$21)+COUNTIF($E20:$E23,$A$3)) -> 0 | X23: =IF($F23="","",COUNTIF($F20:$F23,T$21)+COUNTIF($F20:$F23,$A$3)) -> 0 | Z23: =IF($B23="","",COUNTIF($B20:$B23,Z$21)+COUNTIF($B20:$B23,$A$3)) -> 0 | AA23: =IF($C23="","",COUNTIF($C20:$C23,Z$21)+COUNTIF($C20:$C23,$A$3)) -> 2 | AB23: =IF($D23="","",COUNTIF($D20:$D23,Z$21)+COUNTIF($D20:$D23,$A$3)) -> 1 | AC23: =IF($E23="","",COUNTIF($E20:$E23,Z$21)+COUNTIF($E20:$E23,$A$3)) -> 1 | AD23: =IF($F23="","",COUNTIF($F20:$F23,Z$21)+COUNTIF($F20:$F23,$A$3)) -> 1 | AF23: =IF($B23="","",COUNTIF($B20:$B23,AF$21)+COUNTIF($B20:$B23,$A$3)) -> 0 | AG23: =IF($C23="","",COUNTIF($C20:$C23,AF$21)+COUNTIF($C20:$C23,$A$3)) -> 0 | AH23: =IF($D23="","",COUNTIF($D20:$D23,AF$21)+COUNTIF($D20:$D23,$A$3)) -> 0 | AI23: =IF($E23="","",COUNTIF($E20:$E23,AF$21)+COUNTIF($E20:$E23,$A$3)) -> 0 | AJ23: =IF($F23="","",COUNTIF($F20:$F23,AF$21)+COUNTIF($F20:$F23,$A$3)) -> 0 | AL23: =IF($B23="","",COUNTIF($B20:$B23,AL$21)+COUNTIF($B20:$B23,$A$3)) -> 0 | AM23: =IF($C23="","",COUNTIF($C20:$C23,AL$21)+COUNTIF($C20:$C23,$A$3)) -> 1 | AN23: =IF($D23="","",COUNTIF($D20:$D23,AL$21)+COUNTIF($D20:$D23,$A$3)) -> 0 | AO23: =IF($E23="","",COUNTIF($E20:$E23,AL$21)+COUNTIF($E20:$E23,$A$3)) -> 0 | AP23: =IF($F23="","",COUNTIF($F20:$F23,AL$21)+COUNTIF($F20:$F23,$A$3)) -> 0 | AR23: =IF($B23="","",COUNTIF($B20:$B23,AR$21)+COUNTIF($B20:$B23,$A$3)) -> 0 | AS23: =IF($C23="","",COUNTIF($C20:$C23,AR$21)+COUNTIF($C20:$C23,$A$3)) -> 0 | AT23: =IF($D23="","",COUNTIF($D20:$D23,AR$21)+COUNTIF($D20:$D23,$A$3)) -> 0 | AU23: =IF($E23="","",COUNTIF($E20:$E23,AR$21)+COUNTIF($E20:$E23,$A$3)) -> 0 | AV23: =IF($F23="","",COUNTIF($F20:$F23,AR$21)+COUNTIF($F20:$F23,$A$3)) -> 0 | AX23: =IF($B23="","",COUNTIF($B20:$B23,AX$21)+COUNTIF($B20:$B23,$A$3)) -> 1 | AY23: =IF($C23="","",COUNTIF($C20:$C23,AX$21)+COUNTIF($C20:$C23,$A$3)) -> 0 | AZ23: =IF($D23="","",COUNTIF($D20:$D23,AX$21)+COUNTIF($D20:$D23,$A$3)) -> 1 | BA23: =IF($E23="","",COUNTIF($E20:$E23,AX$21)+COUNTIF($E20:$E23,$A$3)) -> 0 | BB23: =IF($F23="","",COUNTIF($F20:$F23,AX$21)+COUNTIF($F20:$F23,$A$3)) -> 1 | BD23: =IF($B23="","",COUNTIF($B20:$B23,BD$21)+COUNTIF($B20:$B23,$A$3)) -> 0 | BE23: =IF($C23="","",COUNTIF($C20:$C23,BD$21)+COUNTIF($C20:$C23,$A$3)) -> 0 | BF23: =IF($D23="","",COUNTIF($D20:$D23,BD$21)+COUNTIF($D20:$D23,$A$3)) -> 0 | BG23: =IF($E23="","",COUNTIF($E20:$E23,BD$21)+COUNTIF($E20:$E23,$A$3)) -> 0 | BH23: =IF($F23="","",COUNTIF($F20:$F23,BD$21)+COUNTIF($F20:$F23,$A$3)) -> 1 | BJ23: =IF($B23="","",COUNTIF($B20:$B23,BJ$21)+COUNTIF($B20:$B23,$A$3)) -> 2 | BK23: =IF($C23="","",COUNTIF($C20:$C23,BJ$21)+COUNTIF($C20:$C23,$A$3)) -> 0 | BL23: =IF($D23="","",COUNTIF($D20:$D23,BJ$21)+COUNTIF($D20:$D23,$A$3)) -> 1 | BM23: =IF($E23="","",COUNTIF($E20:$E23,BJ$21)+COUNTIF($E20:$E23,$A$3)) -> 1 | BN23: =IF($F23="","",COUNTIF($F20:$F23,BJ$21)+COUNTIF($F20:$F23,$A$3)) -> 1 | BP23: =IF($B23="","",COUNTIF($B20:$B23,BP$21)+COUNTIF($B20:$B23,$A$3)) -> 0 | BQ23: =IF($C23="","",COUNTIF($C20:$C23,BP$21)+COUNTIF($C20:$C23,$A$3)) -> 0 | BR23: =IF($D23="","",COUNTIF($D20:$D23,BP$21)+COUNTIF($D20:$D23,$A$3)) -> 0 | BS23: =IF($E23="","",COUNTIF($E20:$E23,BP$21)+COUNTIF($E20:$E23,$A$3)) -> 1 | BT23: =IF($F23="","",COUNTIF($F20:$F23,BP$21)+COUNTIF($F20:$F23,$A$3)) -> 0
A24: 2 | B24: =IF('Game Info'!J7="","",'Game Info'!J7) -> SYM3 | C24: =IF('Game Info'!K7="","",'Game Info'!K7) -> 9 | D24: =IF('Game Info'!L7="","",'Game Info'!L7) -> K | E24: =IF('Game Info'!M7="","",'Game Info'!M7) -> SYM3 | F24: =IF('Game Info'!N7="","",'Game Info'!N7) -> SYM5 | H24: =IF($B24="","",COUNTIF($B21:$B24,H$21)+COUNTIF($B21:$B24,$A$3)) -> 0 | I24: =IF($C24="","",COUNTIF($C21:$C24,H$21)+COUNTIF($C21:$C24,$A$3)) -> 0 | J24: =IF($D24="","",COUNTIF($D21:$D24,H$21)+COUNTIF($D21:$D24,$A$3)) -> 1 | K24: =IF($E24="","",COUNTIF($E21:$E24,H$21)+COUNTIF($E21:$E24,$A$3)) -> 1 | L24: =IF($F24="","",COUNTIF($F21:$F24,H$21)+COUNTIF($F21:$F24,$A$3)) -> 0 | N24: =IF($B24="","",COUNTIF($B21:$B24,N$21)+COUNTIF($B21:$B24,$A$3)) -> 1 | O24: =IF($C24="","",COUNTIF($C21:$C24,N$21)+COUNTIF($C21:$C24,$A$3)) -> 0 | P24: =IF($D24="","",COUNTIF($D21:$D24,N$21)+COUNTIF($D21:$D24,$A$3)) -> 0 | Q24: =IF($E24="","",COUNTIF($E21:$E24,N$21)+COUNTIF($E21:$E24,$A$3)) -> 0 | R24: =IF($F24="","",COUNTIF($F21:$F24,N$21)+COUNTIF($F21:$F24,$A$3)) -> 0 | T24: =IF($B24="","",COUNTIF($B21:$B24,T$21)+COUNTIF($B21:$B24,$A$3)) -> 1 | U24: =IF($C24="","",COUNTIF($C21:$C24,T$21)+COUNTIF($C21:$C24,$A$3)) -> 0 | V24: =IF($D24="","",COUNTIF($D21:$D24,T$21)+COUNTIF($D21:$D24,$A$3)) -> 0 | W24: =IF($E24="","",COUNTIF($E21:$E24,T$21)+COUNTIF($E21:$E24,$A$3)) -> 1 | X24: =IF($F24="","",COUNTIF($F21:$F24,T$21)+COUNTIF($F21:$F24,$A$3)) -> 0 | Z24: =IF($B24="","",COUNTIF($B21:$B24,Z$21)+COUNTIF($B21:$B24,$A$3)) -> 0 | AA24: =IF($C24="","",COUNTIF($C21:$C24,Z$21)+COUNTIF($C21:$C24,$A$3)) -> 2 | AB24: =IF($D24="","",COUNTIF($D21:$D24,Z$21)+COUNTIF($D21:$D24,$A$3)) -> 1 | AC24: =IF($E24="","",COUNTIF($E21:$E24,Z$21)+COUNTIF($E21:$E24,$A$3)) -> 0 | AD24: =IF($F24="","",COUNTIF($F21:$F24,Z$21)+COUNTIF($F21:$F24,$A$3)) -> 1 | AF24: =IF($B24="","",COUNTIF($B21:$B24,AF$21)+COUNTIF($B21:$B24,$A$3)) -> 0 | AG24: =IF($C24="","",COUNTIF($C21:$C24,AF$21)+COUNTIF($C21:$C24,$A$3)) -> 0 | AH24: =IF($D24="","",COUNTIF($D21:$D24,AF$21)+COUNTIF($D21:$D24,$A$3)) -> 0 | AI24: =IF($E24="","",COUNTIF($E21:$E24,AF$21)+COUNTIF($E21:$E24,$A$3)) -> 0 | AJ24: =IF($F24="","",COUNTIF($F21:$F24,AF$21)+COUNTIF($F21:$F24,$A$3)) -> 1 | AL24: =IF($B24="","",COUNTIF($B21:$B24,AL$21)+COUNTIF($B21:$B24,$A$3)) -> 0 | AM24: =IF($C24="","",COUNTIF($C21:$C24,AL$21)+COUNTIF($C21:$C24,$A$3)) -> 1 | AN24: =IF($D24="","",COUNTIF($D21:$D24,AL$21)+COUNTIF($D21:$D24,$A$3)) -> 0 | AO24: =IF($E24="","",COUNTIF($E21:$E24,AL$21)+COUNTIF($E21:$E24,$A$3)) -> 0 | AP24: =IF($F24="","",COUNTIF($F21:$F24,AL$21)+COUNTIF($F21:$F24,$A$3)) -> 0 | AR24: =IF($B24="","",COUNTIF($B21:$B24,AR$21)+COUNTIF($B21:$B24,$A$3)) -> 0 | AS24: =IF($C24="","",COUNTIF($C21:$C24,AR$21)+COUNTIF($C21:$C24,$A$3)) -> 0 | AT24: =IF($D24="","",COUNTIF($D21:$D24,AR$21)+COUNTIF($D21:$D24,$A$3)) -> 1 | AU24: =IF($E24="","",COUNTIF($E21:$E24,AR$21)+COUNTIF($E21:$E24,$A$3)) -> 0 | AV24: =IF($F24="","",COUNTIF($F21:$F24,AR$21)+COUNTIF($F21:$F24,$A$3)) -> 0 | AX24: =IF($B24="","",COUNTIF($B21:$B24,AX$21)+COUNTIF($B21:$B24,$A$3)) -> 0 | AY24: =IF($C24="","",COUNTIF($C21:$C24,AX$21)+COUNTIF($C21:$C24,$A$3)) -> 0 | AZ24: =IF($D24="","",COUNTIF($D21:$D24,AX$21)+COUNTIF($D21:$D24,$A$3)) -> 1 | BA24: =IF($E24="","",COUNTIF($E21:$E24,AX$21)+COUNTIF($E21:$E24,$A$3)) -> 0 | BB24: =IF($F24="","",COUNTIF($F21:$F24,AX$21)+COUNTIF($F21:$F24,$A$3)) -> 0 | BD24: =IF($B24="","",COUNTIF($B21:$B24,BD$21)+COUNTIF($B21:$B24,$A$3)) -> 0 | BE24: =IF($C24="","",COUNTIF($C21:$C24,BD$21)+COUNTIF($C21:$C24,$A$3)) -> 0 | BF24: =IF($D24="","",COUNTIF($D21:$D24,BD$21)+COUNTIF($D21:$D24,$A$3)) -> 0 | BG24: =IF($E24="","",COUNTIF($E21:$E24,BD$21)+COUNTIF($E21:$E24,$A$3)) -> 0 | BH24: =IF($F24="","",COUNTIF($F21:$F24,BD$21)+COUNTIF($F21:$F24,$A$3)) -> 1 | BJ24: =IF($B24="","",COUNTIF($B21:$B24,BJ$21)+COUNTIF($B21:$B24,$A$3)) -> 2 | BK24: =IF($C24="","",COUNTIF($C21:$C24,BJ$21)+COUNTIF($C21:$C24,$A$3)) -> 0 | BL24: =IF($D24="","",COUNTIF($D21:$D24,BJ$21)+COUNTIF($D21:$D24,$A$3)) -> 0 | BM24: =IF($E24="","",COUNTIF($E21:$E24,BJ$21)+COUNTIF($E21:$E24,$A$3)) -> 1 | BN24: =IF($F24="","",COUNTIF($F21:$F24,BJ$21)+COUNTIF($F21:$F24,$A$3)) -> 1 | BP24: =IF($B24="","",COUNTIF($B21:$B24,BP$21)+COUNTIF($B21:$B24,$A$3)) -> 0 | BQ24: =IF($C24="","",COUNTIF($C21:$C24,BP$21)+COUNTIF($C21:$C24,$A$3)) -> 1 | BR24: =IF($D24="","",COUNTIF($D21:$D24,BP$21)+COUNTIF($D21:$D24,$A$3)) -> 0 | BS24: =IF($E24="","",COUNTIF($E21:$E24,BP$21)+COUNTIF($E21:$E24,$A$3)) -> 1 | BT24: =IF($F24="","",COUNTIF($F21:$F24,BP$21)+COUNTIF($F21:$F24,$A$3)) -> 0
A25: 3 | B25: =IF('Game Info'!J8="","",'Game Info'!J8) -> 9 | C25: =IF('Game Info'!K8="","",'Game Info'!K8) -> SYM2 | D25: =IF('Game Info'!L8="","",'Game Info'!L8) -> 10 | E25: =IF('Game Info'!M8="","",'Game Info'!M8) -> J | F25: =IF('Game Info'!N8="","",'Game Info'!N8) -> Q | H25: =IF($B25="","",COUNTIF($B22:$B25,H$21)+COUNTIF($B22:$B25,$A$3)) -> 0 | I25: =IF($C25="","",COUNTIF($C22:$C25,H$21)+COUNTIF($C22:$C25,$A$3)) -> 0 | J25: =IF($D25="","",COUNTIF($D22:$D25,H$21)+COUNTIF($D22:$D25,$A$3)) -> 1 | K25: =IF($E25="","",COUNTIF($E22:$E25,H$21)+COUNTIF($E22:$E25,$A$3)) -> 1 | L25: =IF($F25="","",COUNTIF($F22:$F25,H$21)+COUNTIF($F22:$F25,$A$3)) -> 0 | N25: =IF($B25="","",COUNTIF($B22:$B25,N$21)+COUNTIF($B22:$B25,$A$3)) -> 1 | O25: =IF($C25="","",COUNTIF($C22:$C25,N$21)+COUNTIF($C22:$C25,$A$3)) -> 1 | P25: =IF($D25="","",COUNTIF($D22:$D25,N$21)+COUNTIF($D22:$D25,$A$3)) -> 0 | Q25: =IF($E25="","",COUNTIF($E22:$E25,N$21)+COUNTIF($E22:$E25,$A$3)) -> 0 | R25: =IF($F25="","",COUNTIF($F22:$F25,N$21)+COUNTIF($F22:$F25,$A$3)) -> 0 | T25: =IF($B25="","",COUNTIF($B22:$B25,T$21)+COUNTIF($B22:$B25,$A$3)) -> 1 | U25: =IF($C25="","",COUNTIF($C22:$C25,T$21)+COUNTIF($C22:$C25,$A$3)) -> 0 | V25: =IF($D25="","",COUNTIF($D22:$D25,T$21)+COUNTIF($D22:$D25,$A$3)) -> 0 | W25: =IF($E25="","",COUNTIF($E22:$E25,T$21)+COUNTIF($E22:$E25,$A$3)) -> 1 | X25: =IF($F25="","",COUNTIF($F22:$F25,T$21)+COUNTIF($F22:$F25,$A$3)) -> 0 | Z25: =IF($B25="","",COUNTIF($B22:$B25,Z$21)+COUNTIF($B22:$B25,$A$3)) -> 0 | AA25: =IF($C25="","",COUNTIF($C22:$C25,Z$21)+COUNTIF($C22:$C25,$A$3)) -> 2 | AB25: =IF($D25="","",COUNTIF($D22:$D25,Z$21)+COUNTIF($D22:$D25,$A$3)) -> 0 | AC25: =IF($E25="","",COUNTIF($E22:$E25,Z$21)+COUNTIF($E22:$E25,$A$3)) -> 0 | AD25: =IF($F25="","",COUNTIF($F22:$F25,Z$21)+COUNTIF($F22:$F25,$A$3)) -> 0 | AF25: =IF($B25="","",COUNTIF($B22:$B25,AF$21)+COUNTIF($B22:$B25,$A$3)) -> 0 | AG25: =IF($C25="","",COUNTIF($C22:$C25,AF$21)+COUNTIF($C22:$C25,$A$3)) -> 0 | AH25: =IF($D25="","",COUNTIF($D22:$D25,AF$21)+COUNTIF($D22:$D25,$A$3)) -> 0 | AI25: =IF($E25="","",COUNTIF($E22:$E25,AF$21)+COUNTIF($E22:$E25,$A$3)) -> 0 | AJ25: =IF($F25="","",COUNTIF($F22:$F25,AF$21)+COUNTIF($F22:$F25,$A$3)) -> 1 | AL25: =IF($B25="","",COUNTIF($B22:$B25,AL$21)+COUNTIF($B22:$B25,$A$3)) -> 0 | AM25: =IF($C25="","",COUNTIF($C22:$C25,AL$21)+COUNTIF($C22:$C25,$A$3)) -> 0 | AN25: =IF($D25="","",COUNTIF($D22:$D25,AL$21)+COUNTIF($D22:$D25,$A$3)) -> 0 | AO25: =IF($E25="","",COUNTIF($E22:$E25,AL$21)+COUNTIF($E22:$E25,$A$3)) -> 0 | AP25: =IF($F25="","",COUNTIF($F22:$F25,AL$21)+COUNTIF($F22:$F25,$A$3)) -> 0 | AR25: =IF($B25="","",COUNTIF($B22:$B25,AR$21)+COUNTIF($B22:$B25,$A$3)) -> 0 | AS25: =IF($C25="","",COUNTIF($C22:$C25,AR$21)+COUNTIF($C22:$C25,$A$3)) -> 0 | AT25: =IF($D25="","",COUNTIF($D22:$D25,AR$21)+COUNTIF($D22:$D25,$A$3)) -> 1 | AU25: =IF($E25="","",COUNTIF($E22:$E25,AR$21)+COUNTIF($E22:$E25,$A$3)) -> 0 | AV25: =IF($F25="","",COUNTIF($F22:$F25,AR$21)+COUNTIF($F22:$F25,$A$3)) -> 0 | AX25: =IF($B25="","",COUNTIF($B22:$B25,AX$21)+COUNTIF($B22:$B25,$A$3)) -> 0 | AY25: =IF($C25="","",COUNTIF($C22:$C25,AX$21)+COUNTIF($C22:$C25,$A$3)) -> 0 | AZ25: =IF($D25="","",COUNTIF($D22:$D25,AX$21)+COUNTIF($D22:$D25,$A$3)) -> 1 | BA25: =IF($E25="","",COUNTIF($E22:$E25,AX$21)+COUNTIF($E22:$E25,$A$3)) -> 0 | BB25: =IF($F25="","",COUNTIF($F22:$F25,AX$21)+COUNTIF($F22:$F25,$A$3)) -> 1 | BD25: =IF($B25="","",COUNTIF($B22:$B25,BD$21)+COUNTIF($B22:$B25,$A$3)) -> 0 | BE25: =IF($C25="","",COUNTIF($C22:$C25,BD$21)+COUNTIF($C22:$C25,$A$3)) -> 0 | BF25: =IF($D25="","",COUNTIF($D22:$D25,BD$21)+COUNTIF($D22:$D25,$A$3)) -> 0 | BG25: =IF($E25="","",COUNTIF($E22:$E25,BD$21)+COUNTIF($E22:$E25,$A$3)) -> 1 | BH25: =IF($F25="","",COUNTIF($F22:$F25,BD$21)+COUNTIF($F22:$F25,$A$3)) -> 1 | BJ25: =IF($B25="","",COUNTIF($B22:$B25,BJ$21)+COUNTIF($B22:$B25,$A$3)) -> 1 | BK25: =IF($C25="","",COUNTIF($C22:$C25,BJ$21)+COUNTIF($C22:$C25,$A$3)) -> 0 | BL25: =IF($D25="","",COUNTIF($D22:$D25,BJ$21)+COUNTIF($D22:$D25,$A$3)) -> 1 | BM25: =IF($E25="","",COUNTIF($E22:$E25,BJ$21)+COUNTIF($E22:$E25,$A$3)) -> 1 | BN25: =IF($F25="","",COUNTIF($F22:$F25,BJ$21)+COUNTIF($F22:$F25,$A$3)) -> 1 | BP25: =IF($B25="","",COUNTIF($B22:$B25,BP$21)+COUNTIF($B22:$B25,$A$3)) -> 1 | BQ25: =IF($C25="","",COUNTIF($C22:$C25,BP$21)+COUNTIF($C22:$C25,$A$3)) -> 1 | BR25: =IF($D25="","",COUNTIF($D22:$D25,BP$21)+COUNTIF($D22:$D25,$A$3)) -> 0 | BS25: =IF($E25="","",COUNTIF($E22:$E25,BP$21)+COUNTIF($E22:$E25,$A$3)) -> 0 | BT25: =IF($F25="","",COUNTIF($F22:$F25,BP$21)+COUNTIF($F22:$F25,$A$3)) -> 0
A26: 4 | B26: =IF('Game Info'!J9="","",'Game Info'!J9) -> SYM2 | C26: =IF('Game Info'!K9="","",'Game Info'!K9) -> J | D26: =IF('Game Info'!L9="","",'Game Info'!L9) -> Q | E26: =IF('Game Info'!M9="","",'Game Info'!M9) -> SYM2 | F26: =IF('Game Info'!N9="","",'Game Info'!N9) -> K | H26: =IF($B26="","",COUNTIF($B23:$B26,H$21)+COUNTIF($B23:$B26,$A$3)) -> 0 | I26: =IF($C26="","",COUNTIF($C23:$C26,H$21)+COUNTIF($C23:$C26,$A$3)) -> 0 | J26: =IF($D26="","",COUNTIF($D23:$D26,H$21)+COUNTIF($D23:$D26,$A$3)) -> 1 | K26: =IF($E26="","",COUNTIF($E23:$E26,H$21)+COUNTIF($E23:$E26,$A$3)) -> 0 | L26: =IF($F26="","",COUNTIF($F23:$F26,H$21)+COUNTIF($F23:$F26,$A$3)) -> 0 | N26: =IF($B26="","",COUNTIF($B23:$B26,N$21)+COUNTIF($B23:$B26,$A$3)) -> 1 | O26: =IF($C26="","",COUNTIF($C23:$C26,N$21)+COUNTIF($C23:$C26,$A$3)) -> 1 | P26: =IF($D26="","",COUNTIF($D23:$D26,N$21)+COUNTIF($D23:$D26,$A$3)) -> 0 | Q26: =IF($E26="","",COUNTIF($E23:$E26,N$21)+COUNTIF($E23:$E26,$A$3)) -> 1 | R26: =IF($F26="","",COUNTIF($F23:$F26,N$21)+COUNTIF($F23:$F26,$A$3)) -> 0 | T26: =IF($B26="","",COUNTIF($B23:$B26,T$21)+COUNTIF($B23:$B26,$A$3)) -> 1 | U26: =IF($C26="","",COUNTIF($C23:$C26,T$21)+COUNTIF($C23:$C26,$A$3)) -> 0 | V26: =IF($D26="","",COUNTIF($D23:$D26,T$21)+COUNTIF($D23:$D26,$A$3)) -> 0 | W26: =IF($E26="","",COUNTIF($E23:$E26,T$21)+COUNTIF($E23:$E26,$A$3)) -> 1 | X26: =IF($F26="","",COUNTIF($F23:$F26,T$21)+COUNTIF($F23:$F26,$A$3)) -> 0 | Z26: =IF($B26="","",COUNTIF($B23:$B26,Z$21)+COUNTIF($B23:$B26,$A$3)) -> 0 | AA26: =IF($C26="","",COUNTIF($C23:$C26,Z$21)+COUNTIF($C23:$C26,$A$3)) -> 1 | AB26: =IF($D26="","",COUNTIF($D23:$D26,Z$21)+COUNTIF($D23:$D26,$A$3)) -> 0 | AC26: =IF($E26="","",COUNTIF($E23:$E26,Z$21)+COUNTIF($E23:$E26,$A$3)) -> 0 | AD26: =IF($F26="","",COUNTIF($F23:$F26,Z$21)+COUNTIF($F23:$F26,$A$3)) -> 0 | AF26: =IF($B26="","",COUNTIF($B23:$B26,AF$21)+COUNTIF($B23:$B26,$A$3)) -> 0 | AG26: =IF($C26="","",COUNTIF($C23:$C26,AF$21)+COUNTIF($C23:$C26,$A$3)) -> 0 | AH26: =IF($D26="","",COUNTIF($D23:$D26,AF$21)+COUNTIF($D23:$D26,$A$3)) -> 0 | AI26: =IF($E26="","",COUNTIF($E23:$E26,AF$21)+COUNTIF($E23:$E26,$A$3)) -> 0 | AJ26: =IF($F26="","",COUNTIF($F23:$F26,AF$21)+COUNTIF($F23:$F26,$A$3)) -> 1 | AL26: =IF($B26="","",COUNTIF($B23:$B26,AL$21)+COUNTIF($B23:$B26,$A$3)) -> 0 | AM26: =IF($C26="","",COUNTIF($C23:$C26,AL$21)+COUNTIF($C23:$C26,$A$3)) -> 0 | AN26: =IF($D26="","",COUNTIF($D23:$D26,AL$21)+COUNTIF($D23:$D26,$A$3)) -> 0 | AO26: =IF($E26="","",COUNTIF($E23:$E26,AL$21)+COUNTIF($E23:$E26,$A$3)) -> 0 | AP26: =IF($F26="","",COUNTIF($F23:$F26,AL$21)+COUNTIF($F23:$F26,$A$3)) -> 0 | AR26: =IF($B26="","",COUNTIF($B23:$B26,AR$21)+COUNTIF($B23:$B26,$A$3)) -> 0 | AS26: =IF($C26="","",COUNTIF($C23:$C26,AR$21)+COUNTIF($C23:$C26,$A$3)) -> 0 | AT26: =IF($D26="","",COUNTIF($D23:$D26,AR$21)+COUNTIF($D23:$D26,$A$3)) -> 1 | AU26: =IF($E26="","",COUNTIF($E23:$E26,AR$21)+COUNTIF($E23:$E26,$A$3)) -> 0 | AV26: =IF($F26="","",COUNTIF($F23:$F26,AR$21)+COUNTIF($F23:$F26,$A$3)) -> 1 | AX26: =IF($B26="","",COUNTIF($B23:$B26,AX$21)+COUNTIF($B23:$B26,$A$3)) -> 0 | AY26: =IF($C26="","",COUNTIF($C23:$C26,AX$21)+COUNTIF($C23:$C26,$A$3)) -> 0 | AZ26: =IF($D26="","",COUNTIF($D23:$D26,AX$21)+COUNTIF($D23:$D26,$A$3)) -> 1 | BA26: =IF($E26="","",COUNTIF($E23:$E26,AX$21)+COUNTIF($E23:$E26,$A$3)) -> 0 | BB26: =IF($F26="","",COUNTIF($F23:$F26,AX$21)+COUNTIF($F23:$F26,$A$3)) -> 1 | BD26: =IF($B26="","",COUNTIF($B23:$B26,BD$21)+COUNTIF($B23:$B26,$A$3)) -> 0 | BE26: =IF($C26="","",COUNTIF($C23:$C26,BD$21)+COUNTIF($C23:$C26,$A$3)) -> 1 | BF26: =IF($D26="","",COUNTIF($D23:$D26,BD$21)+COUNTIF($D23:$D26,$A$3)) -> 0 | BG26: =IF($E26="","",COUNTIF($E23:$E26,BD$21)+COUNTIF($E23:$E26,$A$3)) -> 1 | BH26: =IF($F26="","",COUNTIF($F23:$F26,BD$21)+COUNTIF($F23:$F26,$A$3)) -> 0 | BJ26: =IF($B26="","",COUNTIF($B23:$B26,BJ$21)+COUNTIF($B23:$B26,$A$3)) -> 1 | BK26: =IF($C26="","",COUNTIF($C23:$C26,BJ$21)+COUNTIF($C23:$C26,$A$3)) -> 0 | BL26: =IF($D26="","",COUNTIF($D23:$D26,BJ$21)+COUNTIF($D23:$D26,$A$3)) -> 1 | BM26: =IF($E26="","",COUNTIF($E23:$E26,BJ$21)+COUNTIF($E23:$E26,$A$3)) -> 1 | BN26: =IF($F26="","",COUNTIF($F23:$F26,BJ$21)+COUNTIF($F23:$F26,$A$3)) -> 1 | BP26: =IF($B26="","",COUNTIF($B23:$B26,BP$21)+COUNTIF($B23:$B26,$A$3)) -> 1 | BQ26: =IF($C26="","",COUNTIF($C23:$C26,BP$21)+COUNTIF($C23:$C26,$A$3)) -> 1 | BR26: =IF($D26="","",COUNTIF($D23:$D26,BP$21)+COUNTIF($D23:$D26,$A$3)) -> 0 | BS26: =IF($E26="","",COUNTIF($E23:$E26,BP$21)+COUNTIF($E23:$E26,$A$3)) -> 0 | BT26: =IF($F26="","",COUNTIF($F23:$F26,BP$21)+COUNTIF($F23:$F26,$A$3)) -> 0
A27: 5 | B27: =IF('Game Info'!J10="","",'Game Info'!J10) -> Q | C27: =IF('Game Info'!K10="","",'Game Info'!K10) -> K | D27: =IF('Game Info'!L10="","",'Game Info'!L10) -> SYM5 | E27: =IF('Game Info'!M10="","",'Game Info'!M10) -> SYM2 | F27: =IF('Game Info'!N10="","",'Game Info'!N10) -> J | H27: =IF($B27="","",COUNTIF($B24:$B27,H$21)+COUNTIF($B24:$B27,$A$3)) -> 0 | I27: =IF($C27="","",COUNTIF($C24:$C27,H$21)+COUNTIF($C24:$C27,$A$3)) -> 0 | J27: =IF($D27="","",COUNTIF($D24:$D27,H$21)+COUNTIF($D24:$D27,$A$3)) -> 0 | K27: =IF($E27="","",COUNTIF($E24:$E27,H$21)+COUNTIF($E24:$E27,$A$3)) -> 0 | L27: =IF($F27="","",COUNTIF($F24:$F27,H$21)+COUNTIF($F24:$F27,$A$3)) -> 0 | N27: =IF($B27="","",COUNTIF($B24:$B27,N$21)+COUNTIF($B24:$B27,$A$3)) -> 1 | O27: =IF($C27="","",COUNTIF($C24:$C27,N$21)+COUNTIF($C24:$C27,$A$3)) -> 1 | P27: =IF($D27="","",COUNTIF($D24:$D27,N$21)+COUNTIF($D24:$D27,$A$3)) -> 0 | Q27: =IF($E27="","",COUNTIF($E24:$E27,N$21)+COUNTIF($E24:$E27,$A$3)) -> 2 | R27: =IF($F27="","",COUNTIF($F24:$F27,N$21)+COUNTIF($F24:$F27,$A$3)) -> 0 | T27: =IF($B27="","",COUNTIF($B24:$B27,T$21)+COUNTIF($B24:$B27,$A$3)) -> 1 | U27: =IF($C27="","",COUNTIF($C24:$C27,T$21)+COUNTIF($C24:$C27,$A$3)) -> 0 | V27: =IF($D27="","",COUNTIF($D24:$D27,T$21)+COUNTIF($D24:$D27,$A$3)) -> 0 | W27: =IF($E27="","",COUNTIF($E24:$E27,T$21)+COUNTIF($E24:$E27,$A$3)) -> 1 | X27: =IF($F27="","",COUNTIF($F24:$F27,T$21)+COUNTIF($F24:$F27,$A$3)) -> 0 | Z27: =IF($B27="","",COUNTIF($B24:$B27,Z$21)+COUNTIF($B24:$B27,$A$3)) -> 0 | AA27: =IF($C27="","",COUNTIF($C24:$C27,Z$21)+COUNTIF($C24:$C27,$A$3)) -> 0 | AB27: =IF($D27="","",COUNTIF($D24:$D27,Z$21)+COUNTIF($D24:$D27,$A$3)) -> 0 | AC27: =IF($E27="","",COUNTIF($E24:$E27,Z$21)+COUNTIF($E24:$E27,$A$3)) -> 0 | AD27: =IF($F27="","",COUNTIF($F24:$F27,Z$21)+COUNTIF($F24:$F27,$A$3)) -> 0 | AF27: =IF($B27="","",COUNTIF($B24:$B27,AF$21)+COUNTIF($B24:$B27,$A$3)) -> 0 | AG27: =IF($C27="","",COUNTIF($C24:$C27,AF$21)+COUNTIF($C24:$C27,$A$3)) -> 0 | AH27: =IF($D27="","",COUNTIF($D24:$D27,AF$21)+COUNTIF($D24:$D27,$A$3)) -> 1 | AI27: =IF($E27="","",COUNTIF($E24:$E27,AF$21)+COUNTIF($E24:$E27,$A$3)) -> 0 | AJ27: =IF($F27="","",COUNTIF($F24:$F27,AF$21)+COUNTIF($F24:$F27,$A$3)) -> 1 | AL27: =IF($B27="","",COUNTIF($B24:$B27,AL$21)+COUNTIF($B24:$B27,$A$3)) -> 0 | AM27: =IF($C27="","",COUNTIF($C24:$C27,AL$21)+COUNTIF($C24:$C27,$A$3)) -> 0 | AN27: =IF($D27="","",COUNTIF($D24:$D27,AL$21)+COUNTIF($D24:$D27,$A$3)) -> 0 | AO27: =IF($E27="","",COUNTIF($E24:$E27,AL$21)+COUNTIF($E24:$E27,$A$3)) -> 0 | AP27: =IF($F27="","",COUNTIF($F24:$F27,AL$21)+COUNTIF($F24:$F27,$A$3)) -> 0 | AR27: =IF($B27="","",COUNTIF($B24:$B27,AR$21)+COUNTIF($B24:$B27,$A$3)) -> 0 | AS27: =IF($C27="","",COUNTIF($C24:$C27,AR$21)+COUNTIF($C24:$C27,$A$3)) -> 1 | AT27: =IF($D27="","",COUNTIF($D24:$D27,AR$21)+COUNTIF($D24:$D27,$A$3)) -> 1 | AU27: =IF($E27="","",COUNTIF($E24:$E27,AR$21)+COUNTIF($E24:$E27,$A$3)) -> 0 | AV27: =IF($F27="","",COUNTIF($F24:$F27,AR$21)+COUNTIF($F24:$F27,$A$3)) -> 1 | AX27: =IF($B27="","",COUNTIF($B24:$B27,AX$21)+COUNTIF($B24:$B27,$A$3)) -> 1 | AY27: =IF($C27="","",COUNTIF($C24:$C27,AX$21)+COUNTIF($C24:$C27,$A$3)) -> 0 | AZ27: =IF($D27="","",COUNTIF($D24:$D27,AX$21)+COUNTIF($D24:$D27,$A$3)) -> 1 | BA27: =IF($E27="","",COUNTIF($E24:$E27,AX$21)+COUNTIF($E24:$E27,$A$3)) -> 0 | BB27: =IF($F27="","",COUNTIF($F24:$F27,AX$21)+COUNTIF($F24:$F27,$A$3)) -> 1 | BD27: =IF($B27="","",COUNTIF($B24:$B27,BD$21)+COUNTIF($B24:$B27,$A$3)) -> 0 | BE27: =IF($C27="","",COUNTIF($C24:$C27,BD$21)+COUNTIF($C24:$C27,$A$3)) -> 1 | BF27: =IF($D27="","",COUNTIF($D24:$D27,BD$21)+COUNTIF($D24:$D27,$A$3)) -> 0 | BG27: =IF($E27="","",COUNTIF($E24:$E27,BD$21)+COUNTIF($E24:$E27,$A$3)) -> 1 | BH27: =IF($F27="","",COUNTIF($F24:$F27,BD$21)+COUNTIF($F24:$F27,$A$3)) -> 1 | BJ27: =IF($B27="","",COUNTIF($B24:$B27,BJ$21)+COUNTIF($B24:$B27,$A$3)) -> 0 | BK27: =IF($C27="","",COUNTIF($C24:$C27,BJ$21)+COUNTIF($C24:$C27,$A$3)) -> 0 | BL27: =IF($D27="","",COUNTIF($D24:$D27,BJ$21)+COUNTIF($D24:$D27,$A$3)) -> 1 | BM27: =IF($E27="","",COUNTIF($E24:$E27,BJ$21)+COUNTIF($E24:$E27,$A$3)) -> 0 | BN27: =IF($F27="","",COUNTIF($F24:$F27,BJ$21)+COUNTIF($F24:$F27,$A$3)) -> 0 | BP27: =IF($B27="","",COUNTIF($B24:$B27,BP$21)+COUNTIF($B24:$B27,$A$3)) -> 1 | BQ27: =IF($C27="","",COUNTIF($C24:$C27,BP$21)+COUNTIF($C24:$C27,$A$3)) -> 1 | BR27: =IF($D27="","",COUNTIF($D24:$D27,BP$21)+COUNTIF($D24:$D27,$A$3)) -> 0 | BS27: =IF($E27="","",COUNTIF($E24:$E27,BP$21)+COUNTIF($E24:$E27,$A$3)) -> 0 | BT27: =IF($F27="","",COUNTIF($F24:$F27,BP$21)+COUNTIF($F24:$F27,$A$3)) -> 0
A28: 6 | B28: =IF('Game Info'!J11="","",'Game Info'!J11) -> 10 | C28: =IF('Game Info'!K11="","",'Game Info'!K11) -> SYM1 | D28: =IF('Game Info'!L11="","",'Game Info'!L11) -> J | E28: =IF('Game Info'!M11="","",'Game Info'!M11) -> SYM2 | F28: =IF('Game Info'!N11="","",'Game Info'!N11) -> SYM3 | H28: =IF($B28="","",COUNTIF($B25:$B28,H$21)+COUNTIF($B25:$B28,$A$3)) -> 0 | I28: =IF($C28="","",COUNTIF($C25:$C28,H$21)+COUNTIF($C25:$C28,$A$3)) -> 1 | J28: =IF($D28="","",COUNTIF($D25:$D28,H$21)+COUNTIF($D25:$D28,$A$3)) -> 0 | K28: =IF($E28="","",COUNTIF($E25:$E28,H$21)+COUNTIF($E25:$E28,$A$3)) -> 0 | L28: =IF($F28="","",COUNTIF($F25:$F28,H$21)+COUNTIF($F25:$F28,$A$3)) -> 0 | N28: =IF($B28="","",COUNTIF($B25:$B28,N$21)+COUNTIF($B25:$B28,$A$3)) -> 1 | O28: =IF($C28="","",COUNTIF($C25:$C28,N$21)+COUNTIF($C25:$C28,$A$3)) -> 1 | P28: =IF($D28="","",COUNTIF($D25:$D28,N$21)+COUNTIF($D25:$D28,$A$3)) -> 0 | Q28: =IF($E28="","",COUNTIF($E25:$E28,N$21)+COUNTIF($E25:$E28,$A$3)) -> 3 | R28: =IF($F28="","",COUNTIF($F25:$F28,N$21)+COUNTIF($F25:$F28,$A$3)) -> 0 | T28: =IF($B28="","",COUNTIF($B25:$B28,T$21)+COUNTIF($B25:$B28,$A$3)) -> 0 | U28: =IF($C28="","",COUNTIF($C25:$C28,T$21)+COUNTIF($C25:$C28,$A$3)) -> 0 | V28: =IF($D28="","",COUNTIF($D25:$D28,T$21)+COUNTIF($D25:$D28,$A$3)) -> 0 | W28: =IF($E28="","",COUNTIF($E25:$E28,T$21)+COUNTIF($E25:$E28,$A$3)) -> 0 | X28: =IF($F28="","",COUNTIF($F25:$F28,T$21)+COUNTIF($F25:$F28,$A$3)) -> 1 | Z28: =IF($B28="","",COUNTIF($B25:$B28,Z$21)+COUNTIF($B25:$B28,$A$3)) -> 0 | AA28: =IF($C28="","",COUNTIF($C25:$C28,Z$21)+COUNTIF($C25:$C28,$A$3)) -> 0 | AB28: =IF($D28="","",COUNTIF($D25:$D28,Z$21)+COUNTIF($D25:$D28,$A$3)) -> 0 | AC28: =IF($E28="","",COUNTIF($E25:$E28,Z$21)+COUNTIF($E25:$E28,$A$3)) -> 0 | AD28: =IF($F28="","",COUNTIF($F25:$F28,Z$21)+COUNTIF($F25:$F28,$A$3)) -> 0 | AF28: =IF($B28="","",COUNTIF($B25:$B28,AF$21)+COUNTIF($B25:$B28,$A$3)) -> 0 | AG28: =IF($C28="","",COUNTIF($C25:$C28,AF$21)+COUNTIF($C25:$C28,$A$3)) -> 0 | AH28: =IF($D28="","",COUNTIF($D25:$D28,AF$21)+COUNTIF($D25:$D28,$A$3)) -> 1 | AI28: =IF($E28="","",COUNTIF($E25:$E28,AF$21)+COUNTIF($E25:$E28,$A$3)) -> 0 | AJ28: =IF($F28="","",COUNTIF($F25:$F28,AF$21)+COUNTIF($F25:$F28,$A$3)) -> 0 | AL28: =IF($B28="","",COUNTIF($B25:$B28,AL$21)+COUNTIF($B25:$B28,$A$3)) -> 0 | AM28: =IF($C28="","",COUNTIF($C25:$C28,AL$21)+COUNTIF($C25:$C28,$A$3)) -> 0 | AN28: =IF($D28="","",COUNTIF($D25:$D28,AL$21)+COUNTIF($D25:$D28,$A$3)) -> 0 | AO28: =IF($E28="","",COUNTIF($E25:$E28,AL$21)+COUNTIF($E25:$E28,$A$3)) -> 0 | AP28: =IF($F28="","",COUNTIF($F25:$F28,AL$21)+COUNTIF($F25:$F28,$A$3)) -> 0 | AR28: =IF($B28="","",COUNTIF($B25:$B28,AR$21)+COUNTIF($B25:$B28,$A$3)) -> 0 | AS28: =IF($C28="","",COUNTIF($C25:$C28,AR$21)+COUNTIF($C25:$C28,$A$3)) -> 1 | AT28: =IF($D28="","",COUNTIF($D25:$D28,AR$21)+COUNTIF($D25:$D28,$A$3)) -> 0 | AU28: =IF($E28="","",COUNTIF($E25:$E28,AR$21)+COUNTIF($E25:$E28,$A$3)) -> 0 | AV28: =IF($F28="","",COUNTIF($F25:$F28,AR$21)+COUNTIF($F25:$F28,$A$3)) -> 1 | AX28: =IF($B28="","",COUNTIF($B25:$B28,AX$21)+COUNTIF($B25:$B28,$A$3)) -> 1 | AY28: =IF($C28="","",COUNTIF($C25:$C28,AX$21)+COUNTIF($C25:$C28,$A$3)) -> 0 | AZ28: =IF($D28="","",COUNTIF($D25:$D28,AX$21)+COUNTIF($D25:$D28,$A$3)) -> 1 | BA28: =IF($E28="","",COUNTIF($E25:$E28,AX$21)+COUNTIF($E25:$E28,$A$3)) -> 0 | BB28: =IF($F28="","",COUNTIF($F25:$F28,AX$21)+COUNTIF($F25:$F28,$A$3)) -> 1 | BD28: =IF($B28="","",COUNTIF($B25:$B28,BD$21)+COUNTIF($B25:$B28,$A$3)) -> 0 | BE28: =IF($C28="","",COUNTIF($C25:$C28,BD$21)+COUNTIF($C25:$C28,$A$3)) -> 1 | BF28: =IF($D28="","",COUNTIF($D25:$D28,BD$21)+COUNTIF($D25:$D28,$A$3)) -> 1 | BG28: =IF($E28="","",COUNTIF($E25:$E28,BD$21)+COUNTIF($E25:$E28,$A$3)) -> 1 | BH28: =IF($F28="","",COUNTIF($F25:$F28,BD$21)+COUNTIF($F25:$F28,$A$3)) -> 1 | BJ28: =IF($B28="","",COUNTIF($B25:$B28,BJ$21)+COUNTIF($B25:$B28,$A$3)) -> 1 | BK28: =IF($C28="","",COUNTIF($C25:$C28,BJ$21)+COUNTIF($C25:$C28,$A$3)) -> 0 | BL28: =IF($D28="","",COUNTIF($D25:$D28,BJ$21)+COUNTIF($D25:$D28,$A$3)) -> 1 | BM28: =IF($E28="","",COUNTIF($E25:$E28,BJ$21)+COUNTIF($E25:$E28,$A$3)) -> 0 | BN28: =IF($F28="","",COUNTIF($F25:$F28,BJ$21)+COUNTIF($F25:$F28,$A$3)) -> 0 | BP28: =IF($B28="","",COUNTIF($B25:$B28,BP$21)+COUNTIF($B25:$B28,$A$3)) -> 1 | BQ28: =IF($C28="","",COUNTIF($C25:$C28,BP$21)+COUNTIF($C25:$C28,$A$3)) -> 0 | BR28: =IF($D28="","",COUNTIF($D25:$D28,BP$21)+COUNTIF($D25:$D28,$A$3)) -> 0 | BS28: =IF($E28="","",COUNTIF($E25:$E28,BP$21)+COUNTIF($E25:$E28,$A$3)) -> 0 | BT28: =IF($F28="","",COUNTIF($F25:$F28,BP$21)+COUNTIF($F25:$F28,$A$3)) -> 0
A29: 7 | B29: =IF('Game Info'!J12="","",'Game Info'!J12) -> SYM1 | C29: =IF('Game Info'!K12="","",'Game Info'!K12) -> A | D29: =IF('Game Info'!L12="","",'Game Info'!L12) -> WILD | E29: =IF('Game Info'!M12="","",'Game Info'!M12) -> 9 | F29: =IF('Game Info'!N12="","",'Game Info'!N12) -> 9 | H29: =IF($B29="","",COUNTIF($B26:$B29,H$21)+COUNTIF($B26:$B29,$A$3)) -> 1 | I29: =IF($C29="","",COUNTIF($C26:$C29,H$21)+COUNTIF($C26:$C29,$A$3)) -> 1 | J29: =IF($D29="","",COUNTIF($D26:$D29,H$21)+COUNTIF($D26:$D29,$A$3)) -> 1 | K29: =IF($E29="","",COUNTIF($E26:$E29,H$21)+COUNTIF($E26:$E29,$A$3)) -> 0 | L29: =IF($F29="","",COUNTIF($F26:$F29,H$21)+COUNTIF($F26:$F29,$A$3)) -> 0 | N29: =IF($B29="","",COUNTIF($B26:$B29,N$21)+COUNTIF($B26:$B29,$A$3)) -> 1 | O29: =IF($C29="","",COUNTIF($C26:$C29,N$21)+COUNTIF($C26:$C29,$A$3)) -> 0 | P29: =IF($D29="","",COUNTIF($D26:$D29,N$21)+COUNTIF($D26:$D29,$A$3)) -> 1 | Q29: =IF($E29="","",COUNTIF($E26:$E29,N$21)+COUNTIF($E26:$E29,$A$3)) -> 3 | R29: =IF($F29="","",COUNTIF($F26:$F29,N$21)+COUNTIF($F26:$F29,$A$3)) -> 0 | T29: =IF($B29="","",COUNTIF($B26:$B29,T$21)+COUNTIF($B26:$B29,$A$3)) -> 0 | U29: =IF($C29="","",COUNTIF($C26:$C29,T$21)+COUNTIF($C26:$C29,$A$3)) -> 0 | V29: =IF($D29="","",COUNTIF($D26:$D29,T$21)+COUNTIF($D26:$D29,$A$3)) -> 1 | W29: =IF($E29="","",COUNTIF($E26:$E29,T$21)+COUNTIF($E26:$E29,$A$3)) -> 0 | X29: =IF($F29="","",COUNTIF($F26:$F29,T$21)+COUNTIF($F26:$F29,$A$3)) -> 1 | Z29: =IF($B29="","",COUNTIF($B26:$B29,Z$21)+COUNTIF($B26:$B29,$A$3)) -> 0 | AA29: =IF($C29="","",COUNTIF($C26:$C29,Z$21)+COUNTIF($C26:$C29,$A$3)) -> 0 | AB29: =IF($D29="","",COUNTIF($D26:$D29,Z$21)+COUNTIF($D26:$D29,$A$3)) -> 1 | AC29: =IF($E29="","",COUNTIF($E26:$E29,Z$21)+COUNTIF($E26:$E29,$A$3)) -> 0 | AD29: =IF($F29="","",COUNTIF($F26:$F29,Z$21)+COUNTIF($F26:$F29,$A$3)) -> 0 | AF29: =IF($B29="","",COUNTIF($B26:$B29,AF$21)+COUNTIF($B26:$B29,$A$3)) -> 0 | AG29: =IF($C29="","",COUNTIF($C26:$C29,AF$21)+COUNTIF($C26:$C29,$A$3)) -> 0 | AH29: =IF($D29="","",COUNTIF($D26:$D29,AF$21)+COUNTIF($D26:$D29,$A$3)) -> 2 | AI29: =IF($E29="","",COUNTIF($E26:$E29,AF$21)+COUNTIF($E26:$E29,$A$3)) -> 0 | AJ29: =IF($F29="","",COUNTIF($F26:$F29,AF$21)+COUNTIF($F26:$F29,$A$3)) -> 0 | AL29: =IF($B29="","",COUNTIF($B26:$B29,AL$21)+COUNTIF($B26:$B29,$A$3)) -> 0 | AM29: =IF($C29="","",COUNTIF($C26:$C29,AL$21)+COUNTIF($C26:$C29,$A$3)) -> 1 | AN29: =IF($D29="","",COUNTIF($D26:$D29,AL$21)+COUNTIF($D26:$D29,$A$3)) -> 1 | AO29: =IF($E29="","",COUNTIF($E26:$E29,AL$21)+COUNTIF($E26:$E29,$A$3)) -> 0 | AP29: =IF($F29="","",COUNTIF($F26:$F29,AL$21)+COUNTIF($F26:$F29,$A$3)) -> 0 | AR29: =IF($B29="","",COUNTIF($B26:$B29,AR$21)+COUNTIF($B26:$B29,$A$3)) -> 0 | AS29: =IF($C29="","",COUNTIF($C26:$C29,AR$21)+COUNTIF($C26:$C29,$A$3)) -> 1 | AT29: =IF($D29="","",COUNTIF($D26:$D29,AR$21)+COUNTIF($D26:$D29,$A$3)) -> 1 | AU29: =IF($E29="","",COUNTIF($E26:$E29,AR$21)+COUNTIF($E26:$E29,$A$3)) -> 0 | AV29: =IF($F29="","",COUNTIF($F26:$F29,AR$21)+COUNTIF($F26:$F29,$A$3)) -> 1 | AX29: =IF($B29="","",COUNTIF($B26:$B29,AX$21)+COUNTIF($B26:$B29,$A$3)) -> 1 | AY29: =IF($C29="","",COUNTIF($C26:$C29,AX$21)+COUNTIF($C26:$C29,$A$3)) -> 0 | AZ29: =IF($D29="","",COUNTIF($D26:$D29,AX$21)+COUNTIF($D26:$D29,$A$3)) -> 2 | BA29: =IF($E29="","",COUNTIF($E26:$E29,AX$21)+COUNTIF($E26:$E29,$A$3)) -> 0 | BB29: =IF($F29="","",COUNTIF($F26:$F29,AX$21)+COUNTIF($F26:$F29,$A$3)) -> 0 | BD29: =IF($B29="","",COUNTIF($B26:$B29,BD$21)+COUNTIF($B26:$B29,$A$3)) -> 0 | BE29: =IF($C29="","",COUNTIF($C26:$C29,BD$21)+COUNTIF($C26:$C29,$A$3)) -> 1 | BF29: =IF($D29="","",COUNTIF($D26:$D29,BD$21)+COUNTIF($D26:$D29,$A$3)) -> 2 | BG29: =IF($E29="","",COUNTIF($E26:$E29,BD$21)+COUNTIF($E26:$E29,$A$3)) -> 0 | BH29: =IF($F29="","",COUNTIF($F26:$F29,BD$21)+COUNTIF($F26:$F29,$A$3)) -> 1 | BJ29: =IF($B29="","",COUNTIF($B26:$B29,BJ$21)+COUNTIF($B26:$B29,$A$3)) -> 1 | BK29: =IF($C29="","",COUNTIF($C26:$C29,BJ$21)+COUNTIF($C26:$C29,$A$3)) -> 0 | BL29: =IF($D29="","",COUNTIF($D26:$D29,BJ$21)+COUNTIF($D26:$D29,$A$3)) -> 1 | BM29: =IF($E29="","",COUNTIF($E26:$E29,BJ$21)+COUNTIF($E26:$E29,$A$3)) -> 0 | BN29: =IF($F29="","",COUNTIF($F26:$F29,BJ$21)+COUNTIF($F26:$F29,$A$3)) -> 0 | BP29: =IF($B29="","",COUNTIF($B26:$B29,BP$21)+COUNTIF($B26:$B29,$A$3)) -> 0 | BQ29: =IF($C29="","",COUNTIF($C26:$C29,BP$21)+COUNTIF($C26:$C29,$A$3)) -> 0 | BR29: =IF($D29="","",COUNTIF($D26:$D29,BP$21)+COUNTIF($D26:$D29,$A$3)) -> 1 | BS29: =IF($E29="","",COUNTIF($E26:$E29,BP$21)+COUNTIF($E26:$E29,$A$3)) -> 1 | BT29: =IF($F29="","",COUNTIF($F26:$F29,BP$21)+COUNTIF($F26:$F29,$A$3)) -> 1
A30: 8 | B30: =IF('Game Info'!J13="","",'Game Info'!J13) -> SYM5 | C30: =IF('Game Info'!K13="","",'Game Info'!K13) -> SYM3 | D30: =IF('Game Info'!L13="","",'Game Info'!L13) -> Q | E30: =IF('Game Info'!M13="","",'Game Info'!M13) -> Q | F30: =IF('Game Info'!N13="","",'Game Info'!N13) -> SYM1 | H30: =IF($B30="","",COUNTIF($B27:$B30,H$21)+COUNTIF($B27:$B30,$A$3)) -> 1 | I30: =IF($C30="","",COUNTIF($C27:$C30,H$21)+COUNTIF($C27:$C30,$A$3)) -> 1 | J30: =IF($D30="","",COUNTIF($D27:$D30,H$21)+COUNTIF($D27:$D30,$A$3)) -> 1 | K30: =IF($E30="","",COUNTIF($E27:$E30,H$21)+COUNTIF($E27:$E30,$A$3)) -> 0 | L30: =IF($F30="","",COUNTIF($F27:$F30,H$21)+COUNTIF($F27:$F30,$A$3)) -> 1 | N30: =IF($B30="","",COUNTIF($B27:$B30,N$21)+COUNTIF($B27:$B30,$A$3)) -> 0 | O30: =IF($C30="","",COUNTIF($C27:$C30,N$21)+COUNTIF($C27:$C30,$A$3)) -> 0 | P30: =IF($D30="","",COUNTIF($D27:$D30,N$21)+COUNTIF($D27:$D30,$A$3)) -> 1 | Q30: =IF($E30="","",COUNTIF($E27:$E30,N$21)+COUNTIF($E27:$E30,$A$3)) -> 2 | R30: =IF($F30="","",COUNTIF($F27:$F30,N$21)+COUNTIF($F27:$F30,$A$3)) -> 0 | T30: =IF($B30="","",COUNTIF($B27:$B30,T$21)+COUNTIF($B27:$B30,$A$3)) -> 0 | U30: =IF($C30="","",COUNTIF($C27:$C30,T$21)+COUNTIF($C27:$C30,$A$3)) -> 1 | V30: =IF($D30="","",COUNTIF($D27:$D30,T$21)+COUNTIF($D27:$D30,$A$3)) -> 1 | W30: =IF($E30="","",COUNTIF($E27:$E30,T$21)+COUNTIF($E27:$E30,$A$3)) -> 0 | X30: =IF($F30="","",COUNTIF($F27:$F30,T$21)+COUNTIF($F27:$F30,$A$3)) -> 1 | Z30: =IF($B30="","",COUNTIF($B27:$B30,Z$21)+COUNTIF($B27:$B30,$A$3)) -> 0 | AA30: =IF($C30="","",COUNTIF($C27:$C30,Z$21)+COUNTIF($C27:$C30,$A$3)) -> 0 | AB30: =IF($D30="","",COUNTIF($D27:$D30,Z$21)+COUNTIF($D27:$D30,$A$3)) -> 1 | AC30: =IF($E30="","",COUNTIF($E27:$E30,Z$21)+COUNTIF($E27:$E30,$A$3)) -> 0 | AD30: =IF($F30="","",COUNTIF($F27:$F30,Z$21)+COUNTIF($F27:$F30,$A$3)) -> 0 | AF30: =IF($B30="","",COUNTIF($B27:$B30,AF$21)+COUNTIF($B27:$B30,$A$3)) -> 1 | AG30: =IF($C30="","",COUNTIF($C27:$C30,AF$21)+COUNTIF($C27:$C30,$A$3)) -> 0 | AH30: =IF($D30="","",COUNTIF($D27:$D30,AF$21)+COUNTIF($D27:$D30,$A$3)) -> 2 | AI30: =IF($E30="","",COUNTIF($E27:$E30,AF$21)+COUNTIF($E27:$E30,$A$3)) -> 0 | AJ30: =IF($F30="","",COUNTIF($F27:$F30,AF$21)+COUNTIF($F27:$F30,$A$3)) -> 0 | AL30: =IF($B30="","",COUNTIF($B27:$B30,AL$21)+COUNTIF($B27:$B30,$A$3)) -> 0 | AM30: =IF($C30="","",COUNTIF($C27:$C30,AL$21)+COUNTIF($C27:$C30,$A$3)) -> 1 | AN30: =IF($D30="","",COUNTIF($D27:$D30,AL$21)+COUNTIF($D27:$D30,$A$3)) -> 1 | AO30: =IF($E30="","",COUNTIF($E27:$E30,AL$21)+COUNTIF($E27:$E30,$A$3)) -> 0 | AP30: =IF($F30="","",COUNTIF($F27:$F30,AL$21)+COUNTIF($F27:$F30,$A$3)) -> 0 | AR30: =IF($B30="","",COUNTIF($B27:$B30,AR$21)+COUNTIF($B27:$B30,$A$3)) -> 0 | AS30: =IF($C30="","",COUNTIF($C27:$C30,AR$21)+COUNTIF($C27:$C30,$A$3)) -> 1 | AT30: =IF($D30="","",COUNTIF($D27:$D30,AR$21)+COUNTIF($D27:$D30,$A$3)) -> 1 | AU30: =IF($E30="","",COUNTIF($E27:$E30,AR$21)+COUNTIF($E27:$E30,$A$3)) -> 0 | AV30: =IF($F30="","",COUNTIF($F27:$F30,AR$21)+COUNTIF($F27:$F30,$A$3)) -> 0 | AX30: =IF($B30="","",COUNTIF($B27:$B30,AX$21)+COUNTIF($B27:$B30,$A$3)) -> 1 | AY30: =IF($C30="","",COUNTIF($C27:$C30,AX$21)+COUNTIF($C27:$C30,$A$3)) -> 0 | AZ30: =IF($D30="","",COUNTIF($D27:$D30,AX$21)+COUNTIF($D27:$D30,$A$3)) -> 2 | BA30: =IF($E30="","",COUNTIF($E27:$E30,AX$21)+COUNTIF($E27:$E30,$A$3)) -> 1 | BB30: =IF($F30="","",COUNTIF($F27:$F30,AX$21)+COUNTIF($F27:$F30,$A$3)) -> 0 | BD30: =IF($B30="","",COUNTIF($B27:$B30,BD$21)+COUNTIF($B27:$B30,$A$3)) -> 0 | BE30: =IF($C30="","",COUNTIF($C27:$C30,BD$21)+COUNTIF($C27:$C30,$A$3)) -> 0 | BF30: =IF($D30="","",COUNTIF($D27:$D30,BD$21)+COUNTIF($D27:$D30,$A$3)) -> 2 | BG30: =IF($E30="","",COUNTIF($E27:$E30,BD$21)+COUNTIF($E27:$E30,$A$3)) -> 0 | BH30: =IF($F30="","",COUNTIF($F27:$F30,BD$21)+COUNTIF($F27:$F30,$A$3)) -> 1 | BJ30: =IF($B30="","",COUNTIF($B27:$B30,BJ$21)+COUNTIF($B27:$B30,$A$3)) -> 1 | BK30: =IF($C30="","",COUNTIF($C27:$C30,BJ$21)+COUNTIF($C27:$C30,$A$3)) -> 0 | BL30: =IF($D30="","",COUNTIF($D27:$D30,BJ$21)+COUNTIF($D27:$D30,$A$3)) -> 1 | BM30: =IF($E30="","",COUNTIF($E27:$E30,BJ$21)+COUNTIF($E27:$E30,$A$3)) -> 0 | BN30: =IF($F30="","",COUNTIF($F27:$F30,BJ$21)+COUNTIF($F27:$F30,$A$3)) -> 0 | BP30: =IF($B30="","",COUNTIF($B27:$B30,BP$21)+COUNTIF($B27:$B30,$A$3)) -> 0 | BQ30: =IF($C30="","",COUNTIF($C27:$C30,BP$21)+COUNTIF($C27:$C30,$A$3)) -> 0 | BR30: =IF($D30="","",COUNTIF($D27:$D30,BP$21)+COUNTIF($D27:$D30,$A$3)) -> 1 | BS30: =IF($E30="","",COUNTIF($E27:$E30,BP$21)+COUNTIF($E27:$E30,$A$3)) -> 1 | BT30: =IF($F30="","",COUNTIF($F27:$F30,BP$21)+COUNTIF($F27:$F30,$A$3)) -> 1
