Workbook

Sheet Game Info
B2: Total Bet | C2: 5
B3: Lines | C3: 5
B5: GAME RULES | I5: BASE GAME REELS | Q5: PAYTABLE
B6: WILD matches any other symbol on the payline. Wins with exactly one WILD pay 2x the regular win amount. Wins with exactly two WILD pay 4x the regular win amount. The progressive jackpot is won by getting 3x WILD on line 1. | I6: Pos. | J6: Reel 1 | K6: Weight 1 | L6: Reel 2 | M6: Weight 2 | N6: Reel 3 | O6: Weight 3 | Q6: Symbol | R6: 1x | S6: 2x | T6: 3x
I7: 1 | J7: WILD | K7: 6 | L7: WILD | M7: 3 | N7: WILD | O7: 2 | Q7: WILD | R7: -- | S7: -- | T7: Jackpot | U7: <-- Line 1, only
I8: 2 | J8: BLANK | K8: 8 | L8: BLANK | M8: 8 | N8: BLANK | O8: 1 | Q8: WILD | R8: -- | S8: -- | T8: 1000 | U8: <-- Lines 2 through 5, only
I9: 3 | J9: BAR1 | K9: 15 | L9: BAR1 | M9: 15 | N9: BAR1 | O9: 15 | Q9: SEVEN | R9: -- | S9: -- | T9: 80
I10: 4 | J10: BLANK | K10: 15 | L10: BLANK | M10: 10 | N10: BLANK | O10: 10 | Q10: BAR3 | R10: -- | S10: -- | T10: 40
B11: PAY LINES | I11: 5 | J11: SEVEN | K11: 10 | L11: SEVEN | M11: 5 | N11: SEVEN | O11: 5 | Q11: BAR2 | R11: -- | S11: -- | T11: 25
B12: Line 1 | I12: 6 | J12: BLANK | K12: 15 | L12: BLANK | M12: 10 | N12: BLANK | O12: 10 | Q12: BAR1 | R12: -- | S12: -- | T12: 10
C13: X | D13: X | E13: X | I13: 7 | J13: BAR2 | K13: 15 | L13: BAR2 | M13: 15 | N13: BAR2 | O13: 15 | Q13: ANYBAR | R13: -- | S13: -- | T13: 5
I14: 8 | J14: BLANK | K14: 12 | L14: BLANK | M14: 12 | N14: BLANK | O14: 12 | Q14: CHERRY | R14: 2 | S14: 5 | T14: 10 | U14: <-- CHERRY pays anywhere on a line
I15: 9 | J15: BAR3 | K15: 8 | L15: BAR3 | M15: 8 | N15: BAR3 | O15: 8 | R15: BAR2 | S15: BAR2 | T15: BAR2
B16: Line 2 | C16: X | D16: X | E16: X | I16: 10 | J16: BLANK | K16: 8 | L16: BLANK | M16: 8 | N16: BLANK | O16: 8 | R16: BAR1 | S16: BAR2 | T16: BAR3
I17: 11 | J17: CHERRY | K17: 8 | L17: CHERRY | M17: 8 | N17: CHERRY | O17: 8 | Q17: Jackpot Info
I18: 12 | J18: BLANK | K18: 8 | L18: BLANK | M18: 8 | N18: BLANK | O18: 8 | Q18: Startup | R18: 10000
I19: 13 | J19: BAR1 | K19: 15 | L19: BAR1 | M19: 15 | N19: BAR1 | O19: 15 | Q19: Increment% | R19: 0.01
B20: Line 3 | I20: 14 | J20: BLANK | K20: 10 | L20: BLANK | M20: 10 | N20: BLANK | O20: 8
I21: 15 | J21: BAR3 | K21: 15 | L21: BAR3 | M21: 8 | N21: BAR3 | O21: 5
C22: X | D22: X | E22: X | I22: 16 | J22: BLANK | K22: 10 | L22: BLANK | M22: 10 | N22: BLANK | O22: 8
I23: 17 | J23: BAR2 | K23: 15 | L23: BAR2 | M23: 15 | N23: BAR2 | O23: 15
B24: Line 4 | C24: X | I24: 18 | J24: BLANK | K24: 12 | L24: BLANK | M24: 12 | N24: BLANK | O24: 5
D25: X | I25: 19 | J25: SEVEN | K25: 8 | L25: BAR1 | M25: 5 | N25: SEVEN | O25: 8
E26: X | I26: 20 | J26: BLANK | K26: 8 | L26: BLANK | M26: 8 | N26: BLANK | O26: 1
I27: * Weights are offset based on the center row.
B28: Line 5 | E28: X
D29: X
C30: X

Sheet BG
B2: Line Return | C2: =AVERAGE(F3:F7) -> 0.91832491 | E2: Line | F2: Return (excluding JP) | H2: Jackpot Info
B3: JP Return | C3: =I7 -> 0.020108028 | E3: 1 | F3: =C23 -> 1.0796254 | H3: Startup | I3: ='Game Info'!R18 -> 10000
B4: Total RTP | C4: =SUM(C2:C3) -> 0.93843294 | E4: 2 | F4: 0.94565461 | H4: Increment % | I4: ='Game Info'!R19 -> 0.01
E5: 3 | F5: 0.98557009 | H5: Odds | I5: =1/F44 -> 197862.53
E6: 4 | F6: 0.7846267 | H6: Avg Value | I6: =I3+I5*I4*'Game Info'!C2 -> 19893.126
E7: 5 | F7: 0.79614775 | H7: Return | I7: =I6/I5/'Game Info'!C2 -> 0.020108028
B10: Symbol Distribution - Row 0 | G10: Symbol Distribution - Row 1 | L10: Symbol Distribution - Row 2
B11: Symbol | C11: Reel 1 | D11: Reel 2 | E11: Reel 3 | G11: Symbol | H11: Reel 4 | I11: Reel 5 | J11: Reel 6 | M11: Reel 7 | N11: Reel 8 | O11: Reel 9
B12: WILD | C12: ='Symbol Distribution'!C4 -> 8 | D12: =OFFSET('Symbol Distribution'!D4,,D$10*5) -> 8 | E12: =OFFSET('Symbol Distribution'!E4,,E$10*5) -> 1 | G12: WILD | H12: ='Symbol Distribution'!H4 -> 6 | I12: =OFFSET('Symbol Distribution'!I4,,I$10*5) -> 3 | J12: =OFFSET('Symbol Distribution'!J4,,J$10*5) -> 2 | L12: WILD | M12: ='Symbol Distribution'!M4 -> 8 | N12: =OFFSET('Symbol Distribution'!N4,,N$10*5) -> 8 | O12: =OFFSET('Symbol Distribution'!O4,,O$10*5) -> 1
B13: SEVEN | C13: =OFFSET('Symbol Distribution'!C5,,C$10*5) -> 23 | D13: =OFFSET('Symbol Distribution'!D5,,D$10*5) -> 10 | E13: =OFFSET('Symbol Distribution'!E5,,E$10*5) -> 11 | G13: SEVEN | H13: =OFFSET('Symbol Distribution'!H5,,H$10*5) -> 18 | I13: =OFFSET('Symbol Distribution'!I5,,I$10*5) -> 5 | J13: =OFFSET('Symbol Distribution'!J5,,J$10*5) -> 13 | L13: SEVEN | M13: =OFFSET('Symbol Distribution'!M5,,M$10*5) -> 27 | N13: =OFFSET('Symbol Distribution'!N5,,N$10*5) -> 10 | O13: =OFFSET('Symbol Distribution'!O5,,O$10*5) -> 15
B14: BAR3 | C14: =OFFSET('Symbol Distribution'!C6,,C$10*5) -> 18 | D14: =OFFSET('Symbol Distribution'!D6,,D$10*5) -> 18 | E14: =OFFSET('Symbol Distribution'!E6,,E$10*5) -> 16 | G14: BAR3 | H14: =OFFSET('Symbol Distribution'!H6,,H$10*5) -> 23 | I14: =OFFSET('Symbol Distribution'!I6,,I$10*5) -> 16 | J14: =OFFSET('Symbol Distribution'!J6,,J$10*5) -> 13 | L14: BAR3 | M14: =OFFSET('Symbol Distribution'!M6,,M$10*5) -> 22 | N14: =OFFSET('Symbol Distribution'!N6,,N$10*5) -> 22 | O14: =OFFSET('Symbol Distribution'!O6,,O$10*5) -> 20
B15: BAR2 | C15: =OFFSET('Symbol Distribution'!C7,,C$10*5) -> 24 | D15: =OFFSET('Symbol Distribution'!D7,,D$10*5) -> 24 | E15: =OFFSET('Symbol Distribution'!E7,,E$10*5) -> 17 | G15: BAR2 | H15: =OFFSET('Symbol Distribution'!H7,,H$10*5) -> 30 | I15: =OFFSET('Symbol Distribution'!I7,,I$10*5) -> 30 | J15: =OFFSET('Symbol Distribution'!J7,,J$10*5) -> 30 | L15: BAR2 | M15: =OFFSET('Symbol Distribution'!M7,,M$10*5) -> 25 | N15: =OFFSET('Symbol Distribution'!N7,,N$10*5) -> 20 | O15: =OFFSET('Symbol Distribution'!O7,,O$10*5) -> 18
B16: BAR1 | C16: =OFFSET('Symbol Distribution'!C8,,C$10*5) -> 25 | D16: =OFFSET('Symbol Distribution'!D8,,D$10*5) -> 28 | E16: =OFFSET('Symbol Distribution'!E8,,E$10*5) -> 18 | G16: BAR1 | H16: =OFFSET('Symbol Distribution'!H8,,H$10*5) -> 30 | I16: =OFFSET('Symbol Distribution'!I8,,I$10*5) -> 35 | J16: =OFFSET('Symbol Distribution'!J8,,J$10*5) -> 30 | L16: BAR1 | M16: =OFFSET('Symbol Distribution'!M8,,M$10*5) -> 16 | N16: =OFFSET('Symbol Distribution'!N8,,N$10*5) -> 28 | O16: =OFFSET('Symbol Distribution'!O8,,O$10*5) -> 9
B17: CHERRY | C17: =OFFSET('Symbol Distribution'!C9,,C$10*5) -> 8 | D17: =OFFSET('Symbol Distribution'!D9,,D$10*5) -> 8 | E17: =OFFSET('Symbol Distribution'!E9,,E$10*5) -> 8 | G17: CHERRY | H17: =OFFSET('Symbol Distribution'!H9,,H$10*5) -> 8 | I17: =OFFSET('Symbol Distribution'!I9,,I$10*5) -> 8 | J17: =OFFSET('Symbol Distribution'!J9,,J$10*5) -> 8 | L17: CHERRY | M17: =OFFSET('Symbol Distribution'!M9,,M$10*5) -> 8 | N17: =OFFSET('Symbol Distribution'!N9,,N$10*5) -> 8 | O17: =OFFSET('Symbol Distribution'!O9,,O$10*5) -> 8
B18: BLANK | C18: =OFFSET('Symbol Distribution'!C10,,C$10*5) -> 115 | D18: =OFFSET('Symbol Distribution'!D10,,D$10*5) -> 97 | E18: =OFFSET('Symbol Distribution'!E10,,E$10*5) -> 96 | G18: BLANK | H18: =OFFSET('Symbol Distribution'!H10,,H$10*5) -> 106 | I18: =OFFSET('Symbol Distribution'!I10,,I$10*5) -> 96 | J18: =OFFSET('Symbol Distribution'!J10,,J$10*5) -> 71 | L18: BLANK | M18: =OFFSET('Symbol Distribution'!M10,,M$10*5) -> 115 | N18: =OFFSET('Symbol Distribution'!N10,,N$10*5) -> 97 | O18: =OFFSET('Symbol Distribution'!O10,,O$10*5) -> 96
B19: Total | C19: =SUM(C12:C18) -> 221 | D19: =SUM(D12:D18) -> 193 | E19: =SUM(E12:E18) -> 167 | G19: Total | H19: =SUM(H12:H18) -> 221 | I19: =SUM(I12:I18) -> 193 | J19: =SUM(J12:J18) -> 167 | L19: Total | M19: =SUM(M12:M18) -> 221 | N19: =SUM(N12:N18) -> 193 | O19: =SUM(O12:O18) -> 167
D20: Cycle | E20: =PRODUCT(C19:E19) -> 7123051 | I20: Cycle | J20: =PRODUCT(H19:J19) -> 7123051 | N20: Cycle | O20: =PRODUCT(M19:O19) -> 7123051
B22: Line | C22: 1
B23: Line Return | C23: =SUM(H44:H103) -> 1.0796254
B25: Symbol Distribution - LINE X
B26: Line: | C26: =VLOOKUP($C$22,$G$28:$J$32,2,) -> 1 | D26: =VLOOKUP($C$22,$G$28:$J$32,3,) -> 1 | E26: =VLOOKUP($C$22,$G$28:$J$32,4,) -> 1
B27: Symbol | C27: Reel 1 | D27: Reel 2 | E27: Reel 3 | G27: Symbol | H27: Reel 1 | I27: Reel 2 | J27: Reel 3
B28: WILD | C28: =OFFSET(C12,,C$26*5) -> 6 | D28: =OFFSET(D12,,D$26*5) -> 3 | E28: =OFFSET(E12,,E$26*5) -> 2 | G28: 1 | H28: 1 | I28: 1 | J28: 1
B29: SEVEN | C29: =OFFSET(C13,,C$26*5) -> 18 | D29: =OFFSET(D13,,D$26*5) -> 5 | E29: =OFFSET(E13,,E$26*5) -> 13 | G29: 2 | H29: 0 | I29: 0 | J29: 0
B30: BAR3 | C30: =OFFSET(C14,,C$26*5) -> 23 | D30: =OFFSET(D14,,D$26*5) -> 16 | E30: =OFFSET(E14,,E$26*5) -> 13 | G30: 3 | H30: 2 | I30: 2 | J30: 2
B31: BAR2 | C31: =OFFSET(C15,,C$26*5) -> 30 | D31: =OFFSET(D15,,D$26*5) -> 30 | E31: =OFFSET(E15,,E$26*5) -> 30 | G31: 4 | H31: 0 | I31: 1 | J31: 2
B32: BAR1 | C32: =OFFSET(C16,,C$26*5) -> 30 | D32: =OFFSET(D16,,D$26*5) -> 35 | E32: =OFFSET(E16,,E$26*5) -> 30 | G32: 5 | H32: 2 | I32: 1 | J32: 0
B33: CHERRY | C33: =OFFSET(C17,,C$26*5) -> 8 | D33: =OFFSET(D17,,D$26*5) -> 8 | E33: =OFFSET(E17,,E$26*5) -> 8
B34: BLANK | C34: =OFFSET(C18,,C$26*5) -> 106 | D34: =OFFSET(D18,,D$26*5) -> 96 | E34: =OFFSET(E18,,E$26*5) -> 71
B35: Total | C35: =SUM(C28:C34) -> 221 | D35: =SUM(D28:D34) -> 193 | E35: =SUM(E28:E34) -> 167
D36: Cycle | E36: =PRODUCT(C35:E35) -> 7123051
B38: Derived Symbols
B39: ANYBAR | C39: =SUM(C30:C32) -> 83 | D39: =SUM(D30:D32) -> 81 | E39: =SUM(E30:E32) -> 73
B40: NO CHERRY | C40: =C35-C33-C28 -> 207 | D40: =D35-D33-D28 -> 182 | E40: =E35-E33-E28 -> 157
B42: Combinations
B43: Reel 1 | C43: Reel 2 | D43: Reel 3 | E43: Hits | F43: Prob | G43: Pay | H43: Return
B44: WILD | C44: WILD | D44: WILD | E44: =VLOOKUP(B44,$B$28:$E$40,2,)*VLOOKUP(C44,$B$28:$E$40,3,)*VLOOKUP(D44,$B$28:$E$40,4,) -> 36 | F44: =E44/$E$20 -> 5.0540141e-06 | G44: =IF(C22=1,0,'Game Info'!T8) -> 0 | H44: =F44*G44 -> 0
B46: SEVEN | C46: =B46 -> SEVEN | D46: =B46 -> SEVEN | E46: =VLOOKUP(B46,$B$28:$E$40,2,)*VLOOKUP(C46,$B$28:$E$40,3,)*VLOOKUP(D46,$B$28:$E$40,4,) -> 1170 | F46: =E46/$E$20 -> 0.00016425546 | G46: ='Game Info'!$T$9 -> 80 | H46: =F46*G46 -> 0.013140437
B47: =B46 -> SEVEN | C47: =B46 -> SEVEN | D47: WILD | E47: =VLOOKUP(B47,$B$28:$E$40,2,)*VLOOKUP(C47,$B$28:$E$40,3,)*VLOOKUP(D47,$B$28:$E$40,4,) -> 180 | F47: =E47/$E$20 -> 2.527007e-05 | G47: =2*G46 -> 160 | H47: =F47*G47 -> 0.0040432113
B48: =B46 -> SEVEN | C48: WILD | D48: =B46 -> SEVEN | E48: =VLOOKUP(B48,$B$28:$E$40,2,)*VLOOKUP(C48,$B$28:$E$40,3,)*VLOOKUP(D48,$B$28:$E$40,4,) -> 702 | F48: =E48/$E$20 -> 9.8553274e-05 | G48: =2*G46 -> 160 | H48: =F48*G48 -> 0.015768524
...

Sheet Symbol Distribution
B2: Symbol Distribution - Row 0 | G2: Symbol Distribution - Row 1 | L2: Symbol Distribution - Row 2
B3: Symbol | C3: Reel 1 | D3: Reel 2 | E3: Reel 3 | G3: Symbol | H3: Reel 1 | I3: Reel 2 | J3: Reel 3 | L3: Symbol | M3: Reel 1 | N3: Reel 2 | O3: Reel 3
B4: WILD | C4: =SUMIF(C$16:C$35,$G4,D$17:D$36) -> 8 | D4: =SUMIF(E$16:E$35,$G4,F$17:F$36) -> 8 | E4: =SUMIF(G$16:G$35,$G4,H$17:H$36) -> 1 | G4: WILD | H4: =SUMIF(C$16:C$35,$G4,D$16:D$35) -> 6 | I4: =SUMIF(E$16:E$35,$G4,F$16:F$35) -> 3 | J4: =SUMIF(G$16:G$35,$G4,H$16:H$35) -> 2 | L4: WILD | M4: =SUMIF(C$16:C$35,$G4,D$15:D$34) -> 8 | N4: =SUMIF(E$16:E$35,$G4,F$15:F$34) -> 8 | O4: =SUMIF(G$16:G$35,$G4,H$15:H$34) -> 1
B5: SEVEN | C5: =SUMIF(C$16:C$35,$G5,D$17:D$36) -> 23 | D5: =SUMIF(E$16:E$35,$G5,F$17:F$36) -> 10 | E5: =SUMIF(G$16:G$35,$G5,H$17:H$36) -> 11 | G5: SEVEN | H5: =SUMIF(C$16:C$35,$G5,D$16:D$35) -> 18 | I5: =SUMIF(E$16:E$35,$G5,F$16:F$35) -> 5 | J5: =SUMIF(G$16:G$35,$G5,H$16:H$35) -> 13 | L5: SEVEN | M5: =SUMIF(C$16:C$35,$G5,D$15:D$34) -> 27 | N5: =SUMIF(E$16:E$35,$G5,F$15:F$34) -> 10 | O5: =SUMIF(G$16:G$35,$G5,H$15:H$34) -> 15
B6: BAR3 | C6: =SUMIF(C$16:C$35,$G6,D$17:D$36) -> 18 | D6: =SUMIF(E$16:E$35,$G6,F$17:F$36) -> 18 | E6: =SUMIF(G$16:G$35,$G6,H$17:H$36) -> 16 | G6: BAR3 | H6: =SUMIF(C$16:C$35,$G6,D$16:D$35) -> 23 | I6: =SUMIF(E$16:E$35,$G6,F$16:F$35) -> 16 | J6: =SUMIF(G$16:G$35,$G6,H$16:H$35) -> 13 | L6: BAR3 | M6: =SUMIF(C$16:C$35,$G6,D$15:D$34) -> 22 | N6: =SUMIF(E$16:E$35,$G6,F$15:F$34) -> 22 | O6: =SUMIF(G$16:G$35,$G6,H$15:H$34) -> 20
B7: BAR2 | C7: =SUMIF(C$16:C$35,$G7,D$17:D$36) -> 24 | D7: =SUMIF(E$16:E$35,$G7,F$17:F$36) -> 24 | E7: =SUMIF(G$16:G$35,$G7,H$17:H$36) -> 17 | G7: BAR2 | H7: =SUMIF(C$16:C$35,$G7,D$16:D$35) -> 30 | I7: =SUMIF(E$16:E$35,$G7,F$16:F$35) -> 30 | J7: =SUMIF(G$16:G$35,$G7,H$16:H$35) -> 30 | L7: BAR2 | M7: =SUMIF(C$16:C$35,$G7,D$15:D$34) -> 25 | N7: =SUMIF(E$16:E$35,$G7,F$15:F$34) -> 20 | O7: =SUMIF(G$16:G$35,$G7,H$15:H$34) -> 18
B8: BAR1 | C8: =SUMIF(C$16:C$35,$G8,D$17:D$36) -> 25 | D8: =SUMIF(E$16:E$35,$G8,F$17:F$36) -> 28 | E8: =SUMIF(G$16:G$35,$G8,H$17:H$36) -> 18 | G8: BAR1 | H8: =SUMIF(C$16:C$35,$G8,D$16:D$35) -> 30 | I8: =SUMIF(E$16:E$35,$G8,F$16:F$35) -> 35 | J8: =SUMIF(G$16:G$35,$G8,H$16:H$35) -> 30 | L8: BAR1 | M8: =SUMIF(C$16:C$35,$G8,D$15:D$34) -> 16 | N8: =SUMIF(E$16:E$35,$G8,F$15:F$34) -> 28 | O8: =SUMIF(G$16:G$35,$G8,H$15:H$34) -> 9
B9: CHERRY | C9: =SUMIF(C$16:C$35,$G9,D$17:D$36) -> 8 | D9: =SUMIF(E$16:E$35,$G9,F$17:F$36) -> 8 | E9: =SUMIF(G$16:G$35,$G9,H$17:H$36) -> 8 | G9: CHERRY | H9: =SUMIF(C$16:C$35,$G9,D$16:D$35) -> 8 | I9: =SUMIF(E$16:E$35,$G9,F$16:F$35) -> 8 | J9: =SUMIF(G$16:G$35,$G9,H$16:H$35) -> 8 | L9: CHERRY | M9: =SUMIF(C$16:C$35,$G9,D$15:D$34) -> 8 | N9: =SUMIF(E$16:E$35,$G9,F$15:F$34) -> 8 | O9: =SUMIF(G$16:G$35,$G9,H$15:H$34) -> 8
B10: BLANK | C10: =SUMIF(C$16:C$35,$G10,D$17:D$36) -> 115 | D10: =SUMIF(E$16:E$35,$G10,F$17:F$36) -> 97 | E10: =SUMIF(G$16:G$35,$G10,H$17:H$36) -> 96 | G10: BLANK | H10: =SUMIF(C$16:C$35,$G10,D$16:D$35) -> 106 | I10: =SUMIF(E$16:E$35,$G10,F$16:F$35) -> 96 | J10: =SUMIF(G$16:G$35,$G10,H$16:H$35) -> 71 | L10: BLANK | M10: =SUMIF(C$16:C$35,$G10,D$15:D$34) -> 115 | N10: =SUMIF(E$16:E$35,$G10,F$15:F$34) -> 97 | O10: =SUMIF(G$16:G$35,$G10,H$15:H$34) -> 96
B11: Total | C11: =SUM(C4:C10) -> 221 | D11: =SUM(D4:D10) -> 193 | E11: =SUM(E4:E10) -> 167 | G11: Total | H11: =SUM(H4:H10) -> 221 | I11: =SUM(I4:I10) -> 193 | J11: =SUM(J4:J10) -> 167 | L11: Total | M11: =SUM(M4:M10) -> 221 | N11: =SUM(N4:N10) -> 193 | O11: =SUM(O4:O10) -> 167
B13: BASE GAME REELS
B14: Pos. | C14: Reel 1 | D14: Weight 1 | E14: Reel 2 | F14: Weight 2 | G14: Reel 3 | H14: Weight 3
B15: -- | C15: =C35 -> BLANK | D15: =D35 -> 8 | E15: =E35 -> BLANK | F15: =F35 -> 8 | G15: =G35 -> BLANK | H15: =H35 -> 1
B16: 1 | C16: ='Game Info'!J7 -> WILD | D16: ='Game Info'!K7 -> 6 | E16: ='Game Info'!L7 -> WILD | F16: ='Game Info'!M7 -> 3 | G16: ='Game Info'!N7 -> WILD | H16: ='Game Info'!O7 -> 2
B17: 2 | C17: ='Game Info'!J8 -> BLANK | D17: ='Game Info'!K8 -> 8 | E17: ='Game Info'!L8 -> BLANK | F17: ='Game Info'!M8 -> 8 | G17: ='Game Info'!N8 -> BLANK | H17: ='Game Info'!O8 -> 1
B18: 3 | C18: ='Game Info'!J9 -> BAR1 | D18: ='Game Info'!K9 -> 15 | E18: ='Game Info'!L9 -> BAR1 | F18: ='Game Info'!M9 -> 15 | G18: ='Game Info'!N9 -> BAR1 | H18: ='Game Info'!O9 -> 15
B19: 4 | C19: ='Game Info'!J10 -> BLANK | D19: ='Game Info'!K10 -> 15 | E19: ='Game Info'!L10 -> BLANK | F19: ='Game Info'!M10 -> 10 | G19: ='Game Info'!N10 -> BLANK | H19: ='Game Info'!O10 -> 10
B20: 5 | C20: ='Game Info'!J11 -> SEVEN | D20: ='Game Info'!K11 -> 10 | E20: ='Game Info'!L11 -> SEVEN | F20: ='Game Info'!M11 -> 5 | G20: ='Game Info'!N11 -> SEVEN | H20: ='Game Info'!O11 -> 5
B21: 6 | C21: ='Game Info'!J12 -> BLANK | D21: ='Game Info'!K12 -> 15 | E21: ='Game Info'!L12 -> BLANK | F21: ='Game Info'!M12 -> 10 | G21: ='Game Info'!N12 -> BLANK | H21: ='Game Info'!O12 -> 10
B22: 7 | C22: ='Game Info'!J13 -> BAR2 | D22: ='Game Info'!K13 -> 15 | E22: ='Game Info'!L13 -> BAR2 | F22: ='Game Info'!M13 -> 15 | G22: ='Game Info'!N13 -> BAR2 | H22: ='Game Info'!O13 -> 15
B23: 8 | C23: ='Game Info'!J14 -> BLANK | D23: ='Game Info'!K14 -> 12 | E23: ='Game Info'!L14 -> BLANK | F23: ='Game Info'!M14 -> 12 | G23: ='Game Info'!N14 -> BLANK | H23: ='Game Info'!O14 -> 12
B24: 9 | C24: ='Game Info'!J15 -> BAR3 | D24: ='Game Info'!K15 -> 8 | E24: ='Game Info'!L15 -> BAR3 | F24: ='Game Info'!M15 -> 8 | G24: ='Game Info'!N15 -> BAR3 | H24: ='Game Info'!O15 -> 8
B25: 10 | C25: ='Game Info'!J16 -> BLANK | D25: ='Game Info'!K16 -> 8 | E25: ='Game Info'!L16 -> BLANK | F25: ='Game Info'!M16 -> 8 | G25: ='Game Info'!N16 -> BLANK | H25: ='Game Info'!O16 -> 8
B26: 11 | C26: ='Game Info'!J17 -> CHERRY | D26: ='Game Info'!K17 -> 8 | E26: ='Game Info'!L17 -> CHERRY | F26: ='Game Info'!M17 -> 8 | G26: ='Game Info'!N17 -> CHERRY | H26: ='Game Info'!O17 -> 8
B27: 12 | C27: ='Game Info'!J18 -> BLANK | D27: ='Game Info'!K18 -> 8 | E27: ='Game Info'!L18 -> BLANK | F27: ='Game Info'!M18 -> 8 | G27: ='Game Info'!N18 -> BLANK | H27: ='Game Info'!O18 -> 8
... B35: 20 | C35: ='Game Info'!J26 -> BLANK | D35: ='Game Info'!K26 -> 8 | E35: ='Game Info'!L26 -> BLANK | F35: ='Game Info'!M26 -> 8 | G35: ='Game Info'!N26 -> BLANK | H35: ='Game Info'!O26 -> 1
B36: -- | C36: =C16 -> WILD | D36: =D16 -> 6 | E36: =E16 -> WILD | F36: =F16 -> 3 | G36: =G16 -> WILD | H36: =H16 -> 2
B37: * Weights are offset based on the center row.
