Workbook

Sheet Game Info
B2: Total Bet | C2: 10
B3: Lines | C3: 20
B5: GAME RULES | I5: BASE GAME REELS | P5: FREE GAME REELS | W5: FREE GAME SPINS
B6: WILD substitutes for all symbols except FG. All wins pay left to right except FG. FG wins added to payline wins FG wins multiplied by the total bet. 3, 4, or 5 or more FG awards 8, 12, or 16 free spins, respectively. 3, 4, or 5 or more FG during a free spin awards an additional 8, 12, or 16 free spins, respectively. All wins are tripled during free games. Free games using different reel strips from the base game. | I6: Pos. | J6: Reel 1 | K6: Reel 2 | L6: Reel 3 | M6: Reel 4 | N6: Reel 5 | P6: Pos. | Q6: Reel 1 | R6: Reel 2 | S6: Reel 3 | T6: Reel 4 | U6: Reel 5 | W6: Scats | X6: BG | Y6: FG
I7: 1 | J7: SYM3 | K7: K | L7: SYM1 | M7: SYM1 | N7: J | P7: 1 | Q7: SYM3 | R7: K | S7: SYM1 | T7: SYM1 | U7: J | W7: 5 | X7: 16 | Y7: 16
I8: 2 | J8: K | K8: SYM2 | L8: A | M8: 10 | N8: SYM2 | P8: 2 | Q8: K | R8: SYM2 | S8: A | T8: 10 | U8: SYM2 | W8: 4 | X8: 12 | Y8: 12
I9: 3 | J9: SYM2 | K9: J | L9: SYM4 | M9: SYM3 | N9: K | P9: 3 | Q9: SYM2 | R9: J | S9: SYM4 | T9: SYM3 | U9: K | W9: 3 | X9: 8 | Y9: 8
I10: 4 | J10: 10 | K10: WILD | L10: K | M10: K | N10: SYM3 | P10: 4 | Q10: 10 | R10: WILD | S10: K | T10: K | U10: SYM3
I11: 5 | J11: SYM4 | K11: 9 | L11: J | M11: 10 | N11: 10 | P11: 5 | Q11: SYM4 | R11: 9 | S11: J | T11: 10 | U11: 10 | W11: PAYTABLE
I12: 6 | J12: K | K12: SYM2 | L12: SYM3 | M12: SYM5 | N12: SYM2 | P12: 6 | Q12: K | R12: SYM2 | S12: SYM3 | T12: FG | U12: SYM2 | W12: Symbol | X12: 2x | Y12: 3x | Z12: 4x | AA12: 5x
I13: 7 | J13: SYM1 | K13: A | L13: Q | M13: K | N13: Q | P13: 7 | Q13: J | R13: A | S13: Q | T13: K | U13: Q | W13: WILD | X13: -- | Y13: 100 | Z13: 500 | AA13: 2500
I14: 8 | J14: 10 | K14: SYM3 | L14: SYM2 | M14: SYM4 | N14: FG | P14: 8 | Q14: SYM1 | R14: WILD | S14: SYM2 | T14: SYM4 | U14: FG | W14: SYM1 | X14: -- | Y14: 25 | Z14: 100 | AA14: 750
I15: 9 | J15: SYM3 | K15: 9 | L15: K | M15: A | N15: J | P15: 9 | Q15: A | R15: 9 | S15: K | T15: A | U15: J | W15: SYM2 | X15: -- | Y15: 25 | Z15: 100 | AA15: 750
I16: 10 | J16: J | K16: 10 | L16: WILD | M16: 9 | N16: 9 | P16: 10 | Q16: J | R16: 10 | S16: WILD | T16: 9 | U16: 9 | W16: SYM3 | X16: -- | Y16: 25 | Z16: 100 | AA16: 750
B17: PAY LINES | I17: 11 | J17: SYM3 | K17: SYM4 | L17: A | M17: SYM2 | N17: SYM1 | P17: 11 | Q17: SYM3 | R17: SYM4 | S17: A | T17: SYM2 | U17: SYM1 | W17: SYM4 | X17: -- | Y17: 10 | Z17: 75 | AA17: 250
I18: 12 | J18: 9 | K18: J | L18: SYM3 | M18: K | N18: 10 | P18: 12 | Q18: 9 | R18: J | S18: SYM3 | T18: K | U18: 10 | W18: SYM5 | X18: -- | Y18: 10 | Z18: 50 | AA18: 250
I19: 13 | J19: 10 | K19: SYM2 | L19: 10 | M19: SYM4 | N19: SYM4 | P19: 13 | Q19: 10 | R19: SYM2 | S19: 10 | T19: SYM4 | U19: SYM4 | W19: A | X19: -- | Y19: 10 | Z19: 50 | AA19: 125
I20: 14 | J20: SYM2 | K20: A | L20: K | M20: 10 | N20: Q | P20: 14 | Q20: SYM2 | R20: A | S20: K | T20: 10 | U20: Q | W20: K | X20: -- | Y20: 5 | Z20: 50 | AA20: 100
I21: 15 | J21: A | K21: FG | L21: SYM5 | M21: WILD | N21: WILD | P21: 15 | Q21: A | R21: FG | S21: SYM5 | T21: WILD | U21: WILD | W21: Q | X21: -- | Y21: 5 | Z21: 50 | AA21: 100
I22: 16 | J22: WILD | K22: 9 | L22: J | M22: 9 | N22: A | P22: 16 | Q22: WILD | R22: 9 | S22: J | T22: 9 | U22: A | W22: J | X22: -- | Y22: 5 | Z22: 25 | AA22: 100
I23: 17 | J23: Q | K23: J | L23: SYM3 | M23: SYM3 | N23: SYM5 | P23: 17 | Q23: Q | R23: J | S23: SYM3 | T23: SYM3 | U23: SYM5 | W23: 10 | X23: -- | Y23: 5 | Z23: 25 | AA23: 100
I24: 18 | J24: SYM5 | K24: SYM4 | L24: 10 | M24: Q | N24: 9 | P24: 18 | Q24: SYM5 | R24: SYM4 | S24: 10 | T24: Q | U24: 9 | W24: 9 | X24: -- | Y24: 5 | Z24: 25 | AA24: 100
I25: 19 | J25: K | K25: K | L25: 9 | M25: SYM2 | N25: Q | P25: 19 | Q25: K | R25: K | S25: 9 | T25: SYM2 | U25: Q | W25: FG | X25: -- | Y25: 5 | Z25: 20 | AA25: 100
I26: 20 | J26: A | K26: SYM5 | L26: FG | M26: 10 | N26: SYM4 | P26: 20 | Q26: A | R26: SYM5 | S26: FG | T26: 10 | U26: SYM4 | W26: *FG win is multiplied by total bet.
I27: 21 | J27: SYM4 | K27: Q | L27: Q | M27: J | N27: J | P27: 21 | Q27: SYM4 | R27: Q | S27: Q | T27: J | U27: J
I28: 22 | J28: K | K28: SYM1 | L28: SYM5 | M28: FG | N28: SYM1 | P28: 22 | Q28: K | R28: SYM1 | S28: SYM5 | T28: FG | U28: SYM1
I29: 23 | J29: FG | K29: A | L29: J | M29: A | N29: 10 | P29: 23 | Q29: FG | R29: A | S29: J | T29: A | U29: 10
I30: 24 | J30: Q | K30: 10 | L30: SYM3 | M30: J | N30: 9 | P30: 24 | Q30: Q | R30: 10 | S30: SYM3 | T30: J | U30: 9
I31: 25 | J31: A | K31: SYM2 | L31: 9 | M31: SYM3 | N31: SYM2 | P31: 25 | Q31: A | R31: WILD | S31: 9 | T31: SYM3 | U31: SYM2
I32: 26 | J32: SYM4 | K32: 9 | L32: SYM1 | M32: Q | N32: 10 | P32: 26 | Q32: SYM4 | R32: 9 | S32: WILD | T32: Q | U32: 10
I33: 27 | J33: 9 | K33: SYM3 | L33: K | M33: A | N33: Q | P33: 27 | Q33: 9 | R33: SYM3 | S33: K | T33: A | U33: Q
I34: 28 | J34: Q | K34: J | L34: 10 | M34: SYM2 | N34: SYM3 | P34: 28 | Q34: Q | R34: J | S34: 10 | T34: SYM2 | U34: FG
I35: 29 | J35: WILD | K35: 10 | L35: SYM3 | M35: 9 | N35: 10 | P35: 29 | Q35: WILD | R35: 10 | S35: SYM3 | T35: 9 | U35: 10
I36: 30 | J36: K | K36: FG | L36: Q | M36: SYM4 | N36: SYM5 | P36: 30 | Q36: K | R36: FG | S36: Q | T36: SYM4 | U36: SYM5
I37: 31 | J37: SYM4 | K37: K | L37: SYM2 | M37: K | N37: J | P37: 31 | Q37: SYM4 | R37: K | S37: SYM2 | T37: K | U37: J
I38: 32 | J38: 10 | K38: SYM2 | L38: K | M38: 10 | N38: SYM4 | P38: 32 | Q38: 10 | R38: SYM2 | S38: K | T38: 10 | U38: SYM4
I39: 33 | J39: 9 | K39: J | L39: FG | M39: SYM4 | N39: A | P39: 33 | Q39: 9 | R39: J | S39: FG | T39: SYM4 | U39: A
I40: 34 | J40: SYM2 | K40: SYM1 | L40: J | M40: 9 | N40: K | P40: 34 | Q40: SYM2 | R40: SYM1 | S40: J | T40: 9 | U40: K
I41: 35 | J41: 9 | K41: 9 | L41: SYM3 | M41: SYM5 | N41: SYM5 | P41: 35 | Q41: 9 | R41: 9 | S41: SYM3 | T41: SYM5 | U41: SYM5
I42: 36 | J42: SYM3 | K42: K | L42: 9 | M42: J | N42: Q | P42: 36 | Q42: SYM3 | R42: K | S42: 9 | T42: J | U42: Q
...

Sheet BG
B2: Base Game | C2: =SUM(F39:F74,W39:W54) -> 0.69431468 | F2: Free Games Odds | G2: =1/SUM(U39:U54) -> 134.31835
B3: Free Games | C3: =FG!C5/G2 -> 0.22553469
B4: Total | C4: =C2+C3 -> 0.91984937
B6: Symbol Distribution
B7: Symbol | C7: Reel 1 | D7: Reel 2 | E7: Reel 3 | F7: Reel 4 | G7: Reel 5
B8: WILD | C8: =COUNTIF('Game Info'!J$7:J$170,BG!$B8) -> 2 | D8: =COUNTIF('Game Info'!K$7:K$170,BG!$B8) -> 1 | E8: =COUNTIF('Game Info'!L$7:L$170,BG!$B8) -> 1 | F8: =COUNTIF('Game Info'!M$7:M$170,BG!$B8) -> 1 | G8: =COUNTIF('Game Info'!N$7:N$170,BG!$B8) -> 1
B9: SYM1 | C9: =COUNTIF('Game Info'!J$7:J$170,BG!$B9) -> 2 | D9: =COUNTIF('Game Info'!K$7:K$170,BG!$B9) -> 2 | E9: =COUNTIF('Game Info'!L$7:L$170,BG!$B9) -> 2 | F9: =COUNTIF('Game Info'!M$7:M$170,BG!$B9) -> 1 | G9: =COUNTIF('Game Info'!N$7:N$170,BG!$B9) -> 2
B10: SYM2 | C10: =COUNTIF('Game Info'!J$7:J$170,BG!$B10) -> 4 | D10: =COUNTIF('Game Info'!K$7:K$170,BG!$B10) -> 5 | E10: =COUNTIF('Game Info'!L$7:L$170,BG!$B10) -> 4 | F10: =COUNTIF('Game Info'!M$7:M$170,BG!$B10) -> 3 | G10: =COUNTIF('Game Info'!N$7:N$170,BG!$B10) -> 4
B11: SYM3 | C11: =COUNTIF('Game Info'!J$7:J$170,BG!$B11) -> 4 | D11: =COUNTIF('Game Info'!K$7:K$170,BG!$B11) -> 3 | E11: =COUNTIF('Game Info'!L$7:L$170,BG!$B11) -> 7 | F11: =COUNTIF('Game Info'!M$7:M$170,BG!$B11) -> 3 | G11: =COUNTIF('Game Info'!N$7:N$170,BG!$B11) -> 3
B12: SYM4 | C12: =COUNTIF('Game Info'!J$7:J$170,BG!$B12) -> 6 | D12: =COUNTIF('Game Info'!K$7:K$170,BG!$B12) -> 2 | E12: =COUNTIF('Game Info'!L$7:L$170,BG!$B12) -> 1 | F12: =COUNTIF('Game Info'!M$7:M$170,BG!$B12) -> 4 | G12: =COUNTIF('Game Info'!N$7:N$170,BG!$B12) -> 4
B13: SYM5 | C13: =COUNTIF('Game Info'!J$7:J$170,BG!$B13) -> 2 | D13: =COUNTIF('Game Info'!K$7:K$170,BG!$B13) -> 2 | E13: =COUNTIF('Game Info'!L$7:L$170,BG!$B13) -> 4 | F13: =COUNTIF('Game Info'!M$7:M$170,BG!$B13) -> 2 | G13: =COUNTIF('Game Info'!N$7:N$170,BG!$B13) -> 3
B14: A | C14: =COUNTIF('Game Info'!J$7:J$170,BG!$B14) -> 4 | D14: =COUNTIF('Game Info'!K$7:K$170,BG!$B14) -> 3 | E14: =COUNTIF('Game Info'!L$7:L$170,BG!$B14) -> 2 | F14: =COUNTIF('Game Info'!M$7:M$170,BG!$B14) -> 3 | G14: =COUNTIF('Game Info'!N$7:N$170,BG!$B14) -> 2
B15: K | C15: =COUNTIF('Game Info'!J$7:J$170,BG!$B15) -> 5 | D15: =COUNTIF('Game Info'!K$7:K$170,BG!$B15) -> 4 | E15: =COUNTIF('Game Info'!L$7:L$170,BG!$B15) -> 7 | F15: =COUNTIF('Game Info'!M$7:M$170,BG!$B15) -> 4 | G15: =COUNTIF('Game Info'!N$7:N$170,BG!$B15) -> 2
B16: Q | C16: =COUNTIF('Game Info'!J$7:J$170,BG!$B16) -> 4 | D16: =COUNTIF('Game Info'!K$7:K$170,BG!$B16) -> 1 | E16: =COUNTIF('Game Info'!L$7:L$170,BG!$B16) -> 5 | F16: =COUNTIF('Game Info'!M$7:M$170,BG!$B16) -> 2 | G16: =COUNTIF('Game Info'!N$7:N$170,BG!$B16) -> 6
B17: J | C17: =COUNTIF('Game Info'!J$7:J$170,BG!$B17) -> 3 | D17: =COUNTIF('Game Info'!K$7:K$170,BG!$B17) -> 6 | E17: =COUNTIF('Game Info'!L$7:L$170,BG!$B17) -> 5 | F17: =COUNTIF('Game Info'!M$7:M$170,BG!$B17) -> 3 | G17: =COUNTIF('Game Info'!N$7:N$170,BG!$B17) -> 5
B18: 10 | C18: =COUNTIF('Game Info'!J$7:J$170,BG!$B18) -> 6 | D18: =COUNTIF('Game Info'!K$7:K$170,BG!$B18) -> 4 | E18: =COUNTIF('Game Info'!L$7:L$170,BG!$B18) -> 3 | F18: =COUNTIF('Game Info'!M$7:M$170,BG!$B18) -> 5 | G18: =COUNTIF('Game Info'!N$7:N$170,BG!$B18) -> 6
B19: 9 | C19: =COUNTIF('Game Info'!J$7:J$170,BG!$B19) -> 5 | D19: =COUNTIF('Game Info'!K$7:K$170,BG!$B19) -> 7 | E19: =COUNTIF('Game Info'!L$7:L$170,BG!$B19) -> 4 | F19: =COUNTIF('Game Info'!M$7:M$170,BG!$B19) -> 4 | G19: =COUNTIF('Game Info'!N$7:N$170,BG!$B19) -> 3
B20: FG | C20: =COUNTIF('Game Info'!J$7:J$170,BG!$B20) -> 1 | D20: =COUNTIF('Game Info'!K$7:K$170,BG!$B20) -> 2 | E20: =COUNTIF('Game Info'!L$7:L$170,BG!$B20) -> 2 | F20: =COUNTIF('Game Info'!M$7:M$170,BG!$B20) -> 1 | G20: =COUNTIF('Game Info'!N$7:N$170,BG!$B20) -> 1
B21: Total | C21: =SUM(C8:C20) -> 48 | D21: =SUM(D8:D20) -> 42 | E21: =SUM(E8:E20) -> 47 | F21: =SUM(F8:F20) -> 36 | G21: =SUM(G8:G20) -> 42
F22: Cycle | G22: =PRODUCT(C21:G21) -> 143265024
B24: Derived Symbols
B25: =B9 & " + WILD" -> SYM1 + WILD | C25: =C$8+C9 -> 4 | D25: =D$8+D9 -> 3 | E25: =E$8+E9 -> 3 | F25: =F$8+F9 -> 2 | G25: =G$8+G9 -> 3
B26: =B10 & " + WILD" -> SYM2 + WILD | C26: =C$8+C10 -> 6 | D26: =D$8+D10 -> 6 | E26: =E$8+E10 -> 5 | F26: =F$8+F10 -> 4 | G26: =G$8+G10 -> 5
B27: =B11 & " + WILD" -> SYM3 + WILD | C27: =C$8+C11 -> 6 | D27: =D$8+D11 -> 4 | E27: =E$8+E11 -> 8 | F27: =F$8+F11 -> 4 | G27: =G$8+G11 -> 4
B28: =B12 & " + WILD" -> SYM4 + WILD | C28: =C$8+C12 -> 8 | D28: =D$8+D12 -> 3 | E28: =E$8+E12 -> 2 | F28: =F$8+F12 -> 5 | G28: =G$8+G12 -> 5
B29: =B13 & " + WILD" -> SYM5 + WILD | C29: =C$8+C14 -> 6 | D29: =D$8+D14 -> 4 | E29: =E$8+E14 -> 3 | F29: =F$8+F14 -> 4 | G29: =G$8+G14 -> 3
B30: =B14 & " + WILD" -> A + WILD | C30: =C$8+C15 -> 7 | D30: =D$8+D15 -> 5 | E30: =E$8+E15 -> 8 | F30: =F$8+F15 -> 5 | G30: =G$8+G15 -> 3
B31: =B15 & " + WILD" -> K + WILD | C31: =C$8+C16 -> 6 | D31: =D$8+D16 -> 2 | E31: =E$8+E16 -> 6 | F31: =F$8+F16 -> 3 | G31: =G$8+G16 -> 7
B32: =B16 & " + WILD" -> Q + WILD | C32: =C$8+C17 -> 5 | D32: =D$8+D17 -> 7 | E32: =E$8+E17 -> 6 | F32: =F$8+F17 -> 4 | G32: =G$8+G17 -> 6
B33: =B17 & " + WILD" -> J + WILD | C33: =C$8+C18 -> 8 | D33: =D$8+D18 -> 5 | E33: =E$8+E18 -> 4 | F33: =F$8+F18 -> 6 | G33: =G$8+G18 -> 7
B34: =B18 & " + WILD" -> 10 + WILD | C34: =C$8+C19 -> 7 | D34: =D$8+D19 -> 8 | E34: =E$8+E19 -> 5 | F34: =F$8+F19 -> 5 | G34: =G$8+G19 -> 4
B35: FG (on screen) | C35: =3*C20 -> 3 | D35: =3*D20 -> 6 | E35: =3*E20 -> 6 | F35: =3*F20 -> 3 | G35: =3*G20 -> 3
B37: Line Hits | I37: Scatter Hits
B38: Combination | C38: Hits | D38: Prob | E38: Pay | F38: Contribution | I38: Combination | J38: Reel 1 | K38: Reel 2 | L38: Reel 3 | M38: Reel 4 | N38: Reel 5 | O38: Reel 1 | P38: Reel 2 | Q38: Reel 3 | R38: Reel 4 | S38: Reel 5 | T38: Hits | U38: Prob | V38: Pay | W38: Contribution
B39: =B8 & " x5" -> WILD x5 | C39: =C8*D8*E8*F8*G8 -> 2 | D39: ='Game Info'!$C$3*C39/$G$22 -> 2.7920283e-07 | E39: ='Game Info'!AA13 -> 2500 | F39: =D39*E39/'Game Info'!$C$2 -> 6.9800707e-05 | I39: FG x5 | J39: X | K39: X | L39: X | M39: X | N39: X | O39: =IF(J39="X",C$35,C$21-C$35) -> 3 | P39: =IF(K39="X",D$35,D$21-D$35) -> 6 | Q39: =IF(L39="X",E$35,E$21-E$35) -> 6 | R39: =IF(M39="X",F$35,F$21-F$35) -> 3 | S39: =IF(N39="X",G$35,G$21-G$35) -> 3 | T39: =PRODUCT(O39:S39) -> 972 | U39: =T39/$G$22 -> 6.7846287e-06 | V39: ='Game Info'!AA25 -> 100 | W39: =V39*U39 -> 0.00067846287
B40: =B9 & " x5" -> SYM1 x5 | C40: =C25*D25*E25*F25*G25-$C$8*$D$8*$E$8*$F$8*$G$8 -> 214 | D40: ='Game Info'!$C$3*C40/$G$22 -> 2.9874703e-05 | E40: ='Game Info'!AA14 -> 750 | F40: =D40*E40/'Game Info'!$C$2 -> 0.0022406027 | I40: FG x4 | J40: X | K40: X | L40: X | M40: X | N40: -- | O40: =IF(J40="X",C$35,C$21-C$35) -> 3 | P40: =IF(K40="X",D$35,D$21-D$35) -> 6 | Q40: =IF(L40="X",E$35,E$21-E$35) -> 6 | R40: =IF(M40="X",F$35,F$21-F$35) -> 3 | S40: =IF(N40="X",G$35,G$21-G$35) -> 39 | T40: =PRODUCT(O40:S40) -> 12636 | U40: =T40/$G$22 -> 8.8200174e-05 | V40: ='Game Info'!Z25 -> 20 | W40: =V40*U40 -> 0.0017640035
B41: =B10 & " x5" -> SYM2 x5 | C41: =C26*D26*E26*F26*G26-$C$8*$D$8*$E$8*$F$8*$G$8 -> 3598 | D41: ='Game Info'!$C$3*C41/$G$22 -> 0.00050228589 | E41: ='Game Info'!AA15 -> 750 | F41: =D41*E41/'Game Info'!$C$2 -> 0.037671442 | I41: FG x4 | J41: X | K41: X | L41: X | M41: -- | N41: X | O41: =IF(J41="X",C$35,C$21-C$35) -> 3 | P41: =IF(K41="X",D$35,D$21-D$35) -> 6 | Q41: =IF(L41="X",E$35,E$21-E$35) -> 6 | R41: =IF(M41="X",F$35,F$21-F$35) -> 33 | S41: =IF(N41="X",G$35,G$21-G$35) -> 3 | T41: =PRODUCT(O41:S41) -> 10692 | U41: =T41/$G$22 -> 7.4630916e-05 | V41: =V40 -> 20 | W41: =V41*U41 -> 0.0014926183
B42: =B11 & " x5" -> SYM3 x5 | C42: =C27*D27*E27*F27*G27-$C$8*$D$8*$E$8*$F$8*$G$8 -> 3070 | D42: ='Game Info'!$C$3*C42/$G$22 -> 0.00042857634 | E42: ='Game Info'!AA16 -> 750 | F42: =D42*E42/'Game Info'!$C$2 -> 0.032143226 | I42: FG x4 | J42: X | K42: X | L42: -- | M42: X | N42: X | O42: =IF(J42="X",C$35,C$21-C$35) -> 3 | P42: =IF(K42="X",D$35,D$21-D$35) -> 6 | Q42: =IF(L42="X",E$35,E$21-E$35) -> 41 | R42: =IF(M42="X",F$35,F$21-F$35) -> 3 | S42: =IF(N42="X",G$35,G$21-G$35) -> 3 | T42: =PRODUCT(O42:S42) -> 6642 | U42: =T42/$G$22 -> 4.636163e-05 | V42: =V41 -> 20 | W42: =V42*U42 -> 0.0009272326
B43: =B12 & " x5" -> SYM4 x5 | C43: =(C28*D28*E28*F28-$C$8*$D$8*$E$8*$F$8)*G28 -> 1190 | D43: ='Game Info'!$C$3*C43/$G$22 -> 0.00016612568 | E43: ='Game Info'!AA17 -> 250 | F43: =D43*E43/'Game Info'!$C$2 -> 0.0041531421 | I43: FG x4 | J43: X | K43: -- | L43: X | M43: X | N43: X | O43: =IF(J43="X",C$35,C$21-C$35) -> 3 | P43: =IF(K43="X",D$35,D$21-D$35) -> 36 | Q43: =IF(L43="X",E$35,E$21-E$35) -> 6 | R43: =IF(M43="X",F$35,F$21-F$35) -> 3 | S43: =IF(N43="X",G$35,G$21-G$35) -> 3 | T43: =PRODUCT(O43:S43) -> 5832 | U43: =T43/$G$22 -> 4.0707772e-05 | V43: =V42 -> 20 | W43: =V43*U43 -> 0.00081415545
B44: =B13 & " x5" -> SYM5 x5 | C44: =(C29*D29*E29*F29-$C$8*$D$8*$E$8*$F$8)*G29 -> 858 | D44: ='Game Info'!$C$3*C44/$G$22 -> 0.00011977801 | E44: ='Game Info'!AA18 -> 250 | F44: =D44*E44/'Game Info'!$C$2 -> 0.0029944503 | I44: FG x4 | J44: -- | K44: X | L44: X | M44: X | N44: X | O44: =IF(J44="X",C$35,C$21-C$35) -> 45 | P44: =IF(K44="X",D$35,D$21-D$35) -> 6 | Q44: =IF(L44="X",E$35,E$21-E$35) -> 6 | R44: =IF(M44="X",F$35,F$21-F$35) -> 3 | S44: =IF(N44="X",G$35,G$21-G$35) -> 3 | T44: =PRODUCT(O44:S44) -> 14580 | U44: =T44/$G$22 -> 0.00010176943 | V44: =V43 -> 20 | W44: =V44*U44 -> 0.0020353886
...

Sheet FG
B2: FG Multiplier | C2: 3 | F2: Trigger Prob | G2: Avg Spins | J2: BG Prob | K2: FG Prob | L2: # Spins
B3: Pay per Spin | C3: =C2*SUM(F40:F75,W40:W55) -> 3.1905527 | E3: BG | F3: =SUM(J3:J5) -> 0.0074449993 | G3: =SUMPRODUCT(J3:J5,L3:L5)/SUM(J3:J5) -> 8.1962333 | I3: FG x5 | J3: =BG!U39 -> 6.7846287e-06 | K3: =U40 -> 2.7138515e-05 | L3: ='Game Info'!X7 -> 16
B4: Avg Spins | C4: =G3/(1-F4*G4) -> 9.4947332 | E4: FG | F4: =SUM(K3:K5) -> 0.016540925 | G4: =SUMPRODUCT(K3:K5,L3:L5)/SUM(K3:K5) -> 8.2679792 | I4: FG x4 | J4: =SUM(BG!U40:U44) -> 0.00035166992 | K4: =SUM(U41:U45) -> 0.001053879 | L4: ='Game Info'!X8 -> 12
B5: Total Pay | C5: =C3*C4 -> 30.293447 | I5: FG x3 | J5: =SUM(BG!U45:U54) -> 0.0070865447 | K5: =SUM(U46:U55) -> 0.015459907 | L5: ='Game Info'!X9 -> 8
B7: Symbol Distribution
B8: Symbol | C8: Reel 1 | D8: Reel 2 | E8: Reel 3 | F8: Reel 4 | G8: Reel 5
B9: WILD | C9: =COUNTIF('Game Info'!Q$7:Q$170,$B9) -> 2 | D9: =COUNTIF('Game Info'!R$7:R$170,$B9) -> 3 | E9: =COUNTIF('Game Info'!S$7:S$170,$B9) -> 2 | F9: =COUNTIF('Game Info'!T$7:T$170,$B9) -> 1 | G9: =COUNTIF('Game Info'!U$7:U$170,$B9) -> 1
B10: SYM1 | C10: =COUNTIF('Game Info'!Q$7:Q$170,$B10) -> 2 | D10: =COUNTIF('Game Info'!R$7:R$170,$B10) -> 2 | E10: =COUNTIF('Game Info'!S$7:S$170,$B10) -> 1 | F10: =COUNTIF('Game Info'!T$7:T$170,$B10) -> 1 | G10: =COUNTIF('Game Info'!U$7:U$170,$B10) -> 2
B11: SYM2 | C11: =COUNTIF('Game Info'!Q$7:Q$170,$B11) -> 4 | D11: =COUNTIF('Game Info'!R$7:R$170,$B11) -> 4 | E11: =COUNTIF('Game Info'!S$7:S$170,$B11) -> 4 | F11: =COUNTIF('Game Info'!T$7:T$170,$B11) -> 3 | G11: =COUNTIF('Game Info'!U$7:U$170,$B11) -> 4
B12: SYM3 | C12: =COUNTIF('Game Info'!Q$7:Q$170,$B12) -> 3 | D12: =COUNTIF('Game Info'!R$7:R$170,$B12) -> 2 | E12: =COUNTIF('Game Info'!S$7:S$170,$B12) -> 7 | F12: =COUNTIF('Game Info'!T$7:T$170,$B12) -> 3 | G12: =COUNTIF('Game Info'!U$7:U$170,$B12) -> 2
B13: SYM4 | C13: =COUNTIF('Game Info'!Q$7:Q$170,$B13) -> 6 | D13: =COUNTIF('Game Info'!R$7:R$170,$B13) -> 2 | E13: =COUNTIF('Game Info'!S$7:S$170,$B13) -> 1 | F13: =COUNTIF('Game Info'!T$7:T$170,$B13) -> 4 | G13: =COUNTIF('Game Info'!U$7:U$170,$B13) -> 4
B14: SYM5 | C14: =COUNTIF('Game Info'!Q$7:Q$170,$B14) -> 2 | D14: =COUNTIF('Game Info'!R$7:R$170,$B14) -> 2 | E14: =COUNTIF('Game Info'!S$7:S$170,$B14) -> 4 | F14: =COUNTIF('Game Info'!T$7:T$170,$B14) -> 1 | G14: =COUNTIF('Game Info'!U$7:U$170,$B14) -> 3
B15: A | C15: =COUNTIF('Game Info'!Q$7:Q$170,$B15) -> 5 | D15: =COUNTIF('Game Info'!R$7:R$170,$B15) -> 3 | E15: =COUNTIF('Game Info'!S$7:S$170,$B15) -> 2 | F15: =COUNTIF('Game Info'!T$7:T$170,$B15) -> 3 | G15: =COUNTIF('Game Info'!U$7:U$170,$B15) -> 2
B16: K | C16: =COUNTIF('Game Info'!Q$7:Q$170,$B16) -> 5 | D16: =COUNTIF('Game Info'!R$7:R$170,$B16) -> 4 | E16: =COUNTIF('Game Info'!S$7:S$170,$B16) -> 7 | F16: =COUNTIF('Game Info'!T$7:T$170,$B16) -> 4 | G16: =COUNTIF('Game Info'!U$7:U$170,$B16) -> 2
B17: Q | C17: =COUNTIF('Game Info'!Q$7:Q$170,$B17) -> 4 | D17: =COUNTIF('Game Info'!R$7:R$170,$B17) -> 1 | E17: =COUNTIF('Game Info'!S$7:S$170,$B17) -> 5 | F17: =COUNTIF('Game Info'!T$7:T$170,$B17) -> 2 | G17: =COUNTIF('Game Info'!U$7:U$170,$B17) -> 6
B18: J | C18: =COUNTIF('Game Info'!Q$7:Q$170,$B18) -> 4 | D18: =COUNTIF('Game Info'!R$7:R$170,$B18) -> 6 | E18: =COUNTIF('Game Info'!S$7:S$170,$B18) -> 5 | F18: =COUNTIF('Game Info'!T$7:T$170,$B18) -> 3 | G18: =COUNTIF('Game Info'!U$7:U$170,$B18) -> 5
B19: 10 | C19: =COUNTIF('Game Info'!Q$7:Q$170,$B19) -> 5 | D19: =COUNTIF('Game Info'!R$7:R$170,$B19) -> 4 | E19: =COUNTIF('Game Info'!S$7:S$170,$B19) -> 3 | F19: =COUNTIF('Game Info'!T$7:T$170,$B19) -> 5 | G19: =COUNTIF('Game Info'!U$7:U$170,$B19) -> 6
B20: 9 | C20: =COUNTIF('Game Info'!Q$7:Q$170,$B20) -> 5 | D20: =COUNTIF('Game Info'!R$7:R$170,$B20) -> 7 | E20: =COUNTIF('Game Info'!S$7:S$170,$B20) -> 4 | F20: =COUNTIF('Game Info'!T$7:T$170,$B20) -> 4 | G20: =COUNTIF('Game Info'!U$7:U$170,$B20) -> 3
B21: FG | C21: =COUNTIF('Game Info'!Q$7:Q$170,$B21) -> 1 | D21: =COUNTIF('Game Info'!R$7:R$170,$B21) -> 2 | E21: =COUNTIF('Game Info'!S$7:S$170,$B21) -> 2 | F21: =COUNTIF('Game Info'!T$7:T$170,$B21) -> 2 | G21: =COUNTIF('Game Info'!U$7:U$170,$B21) -> 2
B22: Total | C22: =SUM(C9:C21) -> 48 | D22: =SUM(D9:D21) -> 42 | E22: =SUM(E9:E21) -> 47 | F22: =SUM(F9:F21) -> 36 | G22: =SUM(G9:G21) -> 42
F23: Cycle | G23: =PRODUCT(C22:G22) -> 143265024
B25: Derived Symbols
B26: =B10 & " + WILD" -> SYM1 + WILD | C26: =C$9+C10 -> 4 | D26: =D$9+D10 -> 5 | E26: =E$9+E10 -> 3 | F26: =F$9+F10 -> 2 | G26: =G$9+G10 -> 3
B27: =B11 & " + WILD" -> SYM2 + WILD | C27: =C$9+C11 -> 6 | D27: =D$9+D11 -> 7 | E27: =E$9+E11 -> 6 | F27: =F$9+F11 -> 4 | G27: =G$9+G11 -> 5
B28: =B12 & " + WILD" -> SYM3 + WILD | C28: =C$9+C12 -> 5 | D28: =D$9+D12 -> 5 | E28: =E$9+E12 -> 9 | F28: =F$9+F12 -> 4 | G28: =G$9+G12 -> 3
B29: =B13 & " + WILD" -> SYM4 + WILD | C29: =C$9+C13 -> 8 | D29: =D$9+D13 -> 5 | E29: =E$9+E13 -> 3 | F29: =F$9+F13 -> 5 | G29: =G$9+G13 -> 5
B30: =B14 & " + WILD" -> SYM5 + WILD | C30: =C$9+C15 -> 7 | D30: =D$9+D15 -> 6 | E30: =E$9+E15 -> 4 | F30: =F$9+F15 -> 4 | G30: =G$9+G15 -> 3
B31: =B15 & " + WILD" -> A + WILD | C31: =C$9+C16 -> 7 | D31: =D$9+D16 -> 7 | E31: =E$9+E16 -> 9 | F31: =F$9+F16 -> 5 | G31: =G$9+G16 -> 3
B32: =B16 & " + WILD" -> K + WILD | C32: =C$9+C17 -> 6 | D32: =D$9+D17 -> 4 | E32: =E$9+E17 -> 7 | F32: =F$9+F17 -> 3 | G32: =G$9+G17 -> 7
B33: =B17 & " + WILD" -> Q + WILD | C33: =C$9+C18 -> 6 | D33: =D$9+D18 -> 9 | E33: =E$9+E18 -> 7 | F33: =F$9+F18 -> 4 | G33: =G$9+G18 -> 6
B34: =B18 & " + WILD" -> J + WILD | C34: =C$9+C19 -> 7 | D34: =D$9+D19 -> 7 | E34: =E$9+E19 -> 5 | F34: =F$9+F19 -> 6 | G34: =G$9+G19 -> 7
B35: =B19 & " + WILD" -> 10 + WILD | C35: =C$9+C20 -> 7 | D35: =D$9+D20 -> 10 | E35: =E$9+E20 -> 6 | F35: =F$9+F20 -> 5 | G35: =G$9+G20 -> 4
B36: FG (on screen) | C36: =3*C21 -> 3 | D36: =3*D21 -> 6 | E36: =3*E21 -> 6 | F36: =3*F21 -> 6 | G36: =3*G21 -> 6
B38: Line Hits | I38: Scatter Hits
B39: Combination | C39: Hits | D39: Prob | E39: Pay | F39: Contribution | I39: Combination | J39: Reel 1 | K39: Reel 2 | L39: Reel 3 | M39: Reel 4 | N39: Reel 5 | O39: Reel 1 | P39: Reel 2 | Q39: Reel 3 | R39: Reel 4 | S39: Reel 5 | T39: Hits | U39: Prob | V39: Pay | W39: Contribution
B40: =B9 & " x5" -> WILD x5 | C40: =C9*D9*E9*F9*G9 -> 12 | D40: ='Game Info'!$C$3*C40/$G$23 -> 1.675217e-06 | E40: ='Game Info'!AA13 -> 2500 | F40: =D40*E40/'Game Info'!$C$2 -> 0.00041880424 | I40: FG x5 | J40: X | K40: X | L40: X | M40: X | N40: X | O40: =IF(J40="X",C$36,C$22-C$36) -> 3 | P40: =IF(K40="X",D$36,D$22-D$36) -> 6 | Q40: =IF(L40="X",E$36,E$22-E$36) -> 6 | R40: =IF(M40="X",F$36,F$22-F$36) -> 6 | S40: =IF(N40="X",G$36,G$22-G$36) -> 6 | T40: =PRODUCT(O40:S40) -> 3888 | U40: =T40/$G$23 -> 2.7138515e-05 | V40: ='Game Info'!AA25 -> 100 | W40: =V40*U40 -> 0.0027138515
B41: =B10 & " x5" -> SYM1 x5 | C41: =C26*D26*E26*F26*G26-$C$9*$D$9*$E$9*$F$9*$G$9 -> 348 | D41: ='Game Info'!$C$3*C41/$G$23 -> 4.8581292e-05 | E41: ='Game Info'!AA14 -> 750 | F41: =D41*E41/'Game Info'!$C$2 -> 0.0036435969 | I41: FG x4 | J41: X | K41: X | L41: X | M41: X | N41: -- | O41: =IF(J41="X",C$36,C$22-C$36) -> 3 | P41: =IF(K41="X",D$36,D$22-D$36) -> 6 | Q41: =IF(L41="X",E$36,E$22-E$36) -> 6 | R41: =IF(M41="X",F$36,F$22-F$36) -> 6 | S41: =IF(N41="X",G$36,G$22-G$36) -> 36 | T41: =PRODUCT(O41:S41) -> 23328 | U41: =T41/$G$23 -> 0.00016283109 | V41: ='Game Info'!Z25 -> 20 | W41: =V41*U41 -> 0.0032566218
B42: =B11 & " x5" -> SYM2 x5 | C42: =C27*D27*E27*F27*G27-$C$9*$D$9*$E$9*$F$9*$G$9 -> 5028 | D42: ='Game Info'!$C$3*C42/$G$23 -> 0.00070191591 | E42: ='Game Info'!AA15 -> 750 | F42: =D42*E42/'Game Info'!$C$2 -> 0.052643693 | I42: FG x4 | J42: X | K42: X | L42: X | M42: -- | N42: X | O42: =IF(J42="X",C$36,C$22-C$36) -> 3 | P42: =IF(K42="X",D$36,D$22-D$36) -> 6 | Q42: =IF(L42="X",E$36,E$22-E$36) -> 6 | R42: =IF(M42="X",F$36,F$22-F$36) -> 30 | S42: =IF(N42="X",G$36,G$22-G$36) -> 6 | T42: =PRODUCT(O42:S42) -> 19440 | U42: =T42/$G$23 -> 0.00013569257 | V42: =V41 -> 20 | W42: =V42*U42 -> 0.0027138515
B43: =B12 & " x5" -> SYM3 x5 | C43: =C28*D28*E28*F28*G28-$C$9*$D$9*$E$9*$F$9*$G$9 -> 2688 | D43: ='Game Info'!$C$3*C43/$G$23 -> 0.0003752486 | E43: ='Game Info'!AA16 -> 750 | F43: =D43*E43/'Game Info'!$C$2 -> 0.028143645 | I43: FG x4 | J43: X | K43: X | L43: -- | M43: X | N43: X | O43: =IF(J43="X",C$36,C$22-C$36) -> 3 | P43: =IF(K43="X",D$36,D$22-D$36) -> 6 | Q43: =IF(L43="X",E$36,E$22-E$36) -> 41 | R43: =IF(M43="X",F$36,F$22-F$36) -> 6 | S43: =IF(N43="X",G$36,G$22-G$36) -> 6 | T43: =PRODUCT(O43:S43) -> 26568 | U43: =T43/$G$23 -> 0.00018544652 | V43: =V42 -> 20 | W43: =V43*U43 -> 0.0037089304
B44: =B13 & " x5" -> SYM4 x5 | C44: =(C29*D29*E29*F29-$C$9*$D$9*$E$9*$F$9)*G29 -> 2940 | D44: ='Game Info'!$C$3*C44/$G$23 -> 0.00041042816 | E44: ='Game Info'!AA17 -> 250 | F44: =D44*E44/'Game Info'!$C$2 -> 0.010260704 | I44: FG x4 | J44: X | K44: -- | L44: X | M44: X | N44: X | O44: =IF(J44="X",C$36,C$22-C$36) -> 3 | P44: =IF(K44="X",D$36,D$22-D$36) -> 36 | Q44: =IF(L44="X",E$36,E$22-E$36) -> 6 | R44: =IF(M44="X",F$36,F$22-F$36) -> 6 | S44: =IF(N44="X",G$36,G$22-G$36) -> 6 | T44: =PRODUCT(O44:S44) -> 23328 | U44: =T44/$G$23 -> 0.00016283109 | V44: =V43 -> 20 | W44: =V44*U44 -> 0.0032566218
...
